Workbook
Name PINAJAMAN_KAI_NOV_24: #REF!
Name PINJAMAN_ATS_DES24: #REF!
Name PINJAMAN_ATS_FEB25: #REF!
Name PINJAMAN_ATS_JAN25: #REF!
Name PINJAMAN_ATS_NOV_24: #REF!
Name PINJAMAN_KAI_APR_25: #REF!
Name Pinjaman_KAI_Des24: #REF!
Name PINJAMAN_KAI_FEB25: #REF!
Name Pinjaman_KAI_Jan25: #REF!
Name PINJAMAN_KAI_JULI_25: #REF!
Name PINJAMAN_KAI_JUNI_25: #REF!
Name PINJAMAN_KAI_MAR25: #REF!
Name PINJAMAN_KAI_MEI_25: #REF!
Name TER: TER!$B$2:$U$47

Sheet TER
B2: KATEGORI A | F2: KATEGORI B | J2: KATEGORI C | N2: KATEGORI HARIAN | R2: STATUS | S2: KATEGORI
B3: TK/0 - TK/1 - K/0 | F3: TK/2 - TK/3 - K/1 - K/2 | J3: K/3 | R3: TK/0 | S3: A
B4: 0 | C4: 5400000 | D4: 0 | F4: 0 | G4: 6200000 | H4: 0 | J4: 0 | K4: 6600000 | L4: 0 | N4: ~~ | O4: 450000 | P4: 0 | R4: TK/1 | S4: A
B5: 5400001 | C5: 5650000 | D5: 0.0025 | F5: 6200001 | G5: 6500000 | H5: 0.0025 | J5: 6600001 | K5: 6950000 | L5: 0.0025 | N5: 450001 | O5: 2500000 | P5: 0.005 | R5: K/0 | S5: A
B6: 5650001 | C6: 5950000 | D6: 0.005 | F6: 6500001 | G6: 6850000 | H6: 0.005 | J6: 6950001 | K6: 7350000 | L6: 0.005 | R6: TK/2 | S6: B
B7: 5950001 | C7: 6300000 | D7: 0.0075 | F7: 6850001 | G7: 7300000 | H7: 0.0075 | J7: 7350001 | K7: 7800000 | L7: 0.0075 | R7: TK/3 | S7: B
B8: 6300001 | C8: 6750000 | D8: 0.01 | F8: 7300001 | G8: 9200000 | H8: 0.01 | J8: 7800001 | K8: 8850000 | L8: 0.01 | R8: K/1 | S8: B
B9: 6750001 | C9: 7500000 | D9: 0.0125 | F9: 9200001 | G9: 10750000 | H9: 0.015 | J9: 8850001 | K9: 9800000 | L9: 0.0125 | R9: K/2 | S9: B
B10: 7500001 | C10: 8550000 | D10: 0.015 | F10: 10750001 | G10: 11250000 | H10: 0.02 | J10: 9800001 | K10: 10950000 | L10: 0.015 | R10: K/3 | S10: C
B11: 8550001 | C11: 9650000 | D11: 0.0175 | F11: 11250001 | G11: 11600000 | H11: 0.025 | J11: 10950001 | K11: 11200000 | L11: 0.0175
B12: 9650001 | C12: 10050000 | D12: 0.02 | F12: 11600001 | G12: 12600000 | H12: 0.03 | J12: 11200001 | K12: 12050000 | L12: 0.02
B13: 10050001 | C13: 10350000 | D13: 0.0225 | F13: 12600001 | G13: 13600000 | H13: 0.04 | J13: 12050001 | K13: 12950000 | L13: 0.03
B14: 10350001 | C14: 10700000 | D14: 0.025 | F14: 13600001 | G14: 14950000 | H14: 0.05 | J14: 12950001 | K14: 14150000 | L14: 0.04
B15: 10700001 | C15: 11050000 | D15: 0.03 | F15: 14950001 | G15: 16400000 | H15: 0.06 | J15: 14150001 | K15: 15550000 | L15: 0.05
B16: 11050001 | C16: 11600000 | D16: 0.035 | F16: 16400001 | G16: 18450000 | H16: 0.07 | J16: 15550001 | K16: 17050000 | L16: 0.06
B17: 11600001 | C17: 12500000 | D17: 0.04 | F17: 18450001 | G17: 21850000 | H17: 0.08 | J17: 17050001 | K17: 19500000 | L17: 0.07
B18: 12500001 | C18: 13750000 | D18: 0.05 | F18: 21850001 | G18: 26000000 | H18: 0.09 | J18: 19500001 | K18: 22700000 | L18: 0.08
B19: 13750001 | C19: 15100000 | D19: 0.06 | F19: 26000001 | G19: 27700000 | H19: 0.1 | J19: 22700001 | K19: 26600000 | L19: 0.09
B20: 15100001 | C20: 16950000 | D20: 0.07 | F20: 27700001 | G20: 29350000 | H20: 0.11 | J20: 26600001 | K20: 28100000 | L20: 0.1
B21: 16950001 | C21: 19750000 | D21: 0.08 | F21: 29350001 | G21: 31450000 | H21: 0.12 | J21: 28100001 | K21: 30100000 | L21: 0.11
B22: 19750001 | C22: 24150000 | D22: 0.09 | F22: 31450001 | G22: 33950000 | H22: 0.13 | J22: 30100001 | K22: 32600000 | L22: 0.12
... B42: 337000001 | C42: 454000000 | D42: 0.29 | F42: 957000001 | G42: 1405000000 | H42: 0.33 | J42: 709000001 | K42: 965000000 | L42: 0.32
B43: 454000001 | C43: 550000000 | D43: 0.3 | F43: 1405000001 | G43: ~~ | H43: 0.34 | J43: 965000001 | K43: 1419000000 | L43: 0.33
B44: 550000001 | C44: 695000000 | D44: 0.31 | J44: 1419000001 | K44: ~~ | L44: 0.34
B45: 695000001 | C45: 910000000 | D45: 0.32
B46: 910000001 | C46: 1400000000 | D46: 0.33
B47: 1400000001 | C47: ~~ | D47: 0.34

Sheet 01. Januari 26
AF2: 468.468 | AG2: 253.5
B3: NO. | C3: NIK KTP | D3: NAMA | E3: REKENING | G3: JABATAN | H3: STATUS | I3: PENAMBAH | Z3: PENGURANG | AN3: UPAH | AO3: PPh | AP3: UPAH (-PPh) | AQ3: UPAH (-THR) | AR3: THP (ROUNDED) | AT3: PPh
E4: BANK | F4: NOMOR | I4: GAJI POKOK | J4: BPJS | L4: TUNJANGAN KINERJA (TUKIN) | R4: KROSCEK | U4: BACKUP | X4: BONUS/ THR | Y4: SUB TOTAL | Z4: KETIDAKHADIRAN | AF4: BPJS | AH4: SP | AI4: PINJAMAN | AL4: LAIN-LAIN | AM4: SUB TOTAL | AT4: STATUS | AU4: KAT TER | AV4: GAJI POKOK | AW4: TUKIN | AX4: BACKUP | AY4: BONUS/ THR | AZ4: BPJS | BC4: UPAH | BD4: TARIF | BE4: PPh
J5: TK | K5: KES | L5: BUDGET | M5: 1 HARI | N5: HARI KERJA | O5: SCHEDULE | P5: TOTAL | R5: BUDGET | S5: REALISASI | T5: MINUS | U5: NOMINAL | V5: HARI OT | W5: TOTAL | Z5: SAKIT | AA5: IJIN | AB5: CUTI | AC5: TK | AD5: SOC-A | AE5: TOTAL | AF5: TK | AG5: KES | AI5: SALDO | AJ5: POTONGAN | AK5: SISA | AZ5: TK - JKK | BA5: TK - JKM | BB5: KES
B6: 1 | C6: 3175090709870002 | D6: RANGGA HADI WIJAYA | E6: BRI | F6: 065101021314508 | G6: ANGGOTA | H6: FULL - EXISTING | I6: =IF(H6="FULL - EXISTING",5729876,5729876/O6*N6) -> 5729876 | J6: 316368 | K6: 203800 | L6: 200000 | M6: =L6/O6 -> 10000 | N6: =IFERROR(__xludf.DUMMYFUNCTION("VLOOKUP(C6,IMPORTRANGE(""https://docs.google.com/spreadsheets/d/1ZLN5T8y7NSBIP1rvSj6TTUR_vTQbRwUKSt8zZJ_EfE4/edit?gid=461094331#gid=461094331"",""SCHEDULE_SDT_JAN26""),35,0)"),20) -> 20 | O6: =IFERROR(__xludf.DUMMYFUNCTION("VLOOKUP(C6,IMPORTRANGE(""https://docs.google.com/spreadsheets/d/1ZLN5T8y7NSBIP1rvSj6TTUR_vTQbRwUKSt8zZJ_EfE4/edit?gid=461094331#gid=461094331"",""SCHEDULE_SDT_JAN26""),34,0)"),20) -> 20 | P6: =M6*N6 -> 200000 | R6: =I6+J6+K6+L6 -> 6450044 | S6: =I6+J6+K6+L6 -> 6450044 | T6: =IF(R6-S6<0,R6-S6,0) -> 0 | U6: 250000 | V6: =IFERROR(__xludf.DUMMYFUNCTION("VLOOKUP(C6,IMPORTRANGE(""https://docs.google.com/spreadsheets/d/1ZLN5T8y7NSBIP1rvSj6TTUR_vTQbRwUKSt8zZJ_EfE4/edit?gid=461094331#gid=461094331"",""SCHEDULE_SDT_JAN26""),36,0)"),1) -> 1 | W6: =U6*V6 -> 250000 | X6: 0 | Y6: =I6+J6+K6+P6+W6+X6 -> 6700044 | Z6: =IFERROR(__xludf.DUMMYFUNCTION("VLOOKUP(C6,IMPORTRANGE(""https://docs.google.com/spreadsheets/d/1ZLN5T8y7NSBIP1rvSj6TTUR_vTQbRwUKSt8zZJ_EfE4/edit?gid=461094331#gid=461094331"",""SCHEDULE_SDT_JAN26""),38,0)+VLOOKUP(C6,IMPORTRANGE(""https://docs.google.com/spreadsheets/d/1ZLN5T8y7NSBIP1rv"&"Sj6TTUR_vTQbRwUKSt8zZJ_EfE4/edit?gid=461094331#gid=461094331"",""SCHEDULE_SDT_JAN26""),39,0)"),0) -> 0 | AA6: =IFERROR(__xludf.DUMMYFUNCTION("VLOOKUP(C6,IMPORTRANGE(""https://docs.google.com/spreadsheets/d/1ZLN5T8y7NSBIP1rvSj6TTUR_vTQbRwUKSt8zZJ_EfE4/edit?gid=461094331#gid=461094331"",""SCHEDULE_SDT_JAN26""),40,0)"),0) -> 0 | AB6: =IFERROR(__xludf.DUMMYFUNCTION("VLOOKUP(C6,IMPORTRANGE(""https://docs.google.com/spreadsheets/d/1ZLN5T8y7NSBIP1rvSj6TTUR_vTQbRwUKSt8zZJ_EfE4/edit?gid=461094331#gid=461094331"",""SCHEDULE_SDT_JAN26""),41,0)"),0) -> 0 | AC6: =IFERROR(__xludf.DUMMYFUNCTION("VLOOKUP(C6,IMPORTRANGE(""https://docs.google.com/spreadsheets/d/1ZLN5T8y7NSBIP1rvSj6TTUR_vTQbRwUKSt8zZJ_EfE4/edit?gid=461094331#gid=461094331"",""SCHEDULE_SDT_JAN26""),42,0)"),0) -> 0 | AD6: =IFERROR(__xludf.DUMMYFUNCTION("VLOOKUP(C6,IMPORTRANGE(""https://docs.google.com/spreadsheets/d/1ZLN5T8y7NSBIP1rvSj6TTUR_vTQbRwUKSt8zZJ_EfE4/edit?gid=461094331#gid=461094331"",""SCHEDULE_SDT_JAN26""),43,0)"),0) -> 0 | AE6: =U6*(Z6+AA6+AD6+(AC6)) -> 0 | AF6: 468468 | AG6: 253500 | AH6: 0 | AI6: 0 | AJ6: 0 | AK6: =AI6-AJ6 -> 0 | AL6: 0 | AM6: =AE6+AF6+AG6+AH6+AJ6+AL6 -> 721968 | AN6: =Y6-AM6 -> 5978076 | AO6: =BE6 -> 0 | AP6: =AN6-AO6 -> 5978076 | AQ6: =AP6-X6 -> 5978076 | AR6: =IF(AQ6>0,ROUND(AQ6,-2),0) -> 5978100 | AT6: K/3 | AU6: C | AV6: =I6 -> 5729876 | AW6: =P6 -> 200000 | AX6: =W6 -> 250000 | AY6: 0 | AZ6: =IF(J6=0,0,AV6*0.24%) -> 13751.702 | BA6: =IF(J6=0,0,AV6*0.3%) -> 17189.628 | BB6: =IF(K6=0,0,AV6*4%) -> 229195.04 | BC6: =SUM(AV6:BB6) -> 6440012.4 | BD6: =IF(AU6="C",VLOOKUP(BC6,TER!$J$4:$L$50,3,TRUE),IF(AU6="B",VLOOKUP(BC6,TER!$F$4:$H$50,3,TRUE),IF(AU6="A",VLOOKUP(BC6,TER!$B$4:$D$50,3,TRUE),"ERROR"))) -> 0 | BE6: =BC6*BD6 -> 0
B7: 2 | C7: 2101067103820002 | D7: NUNY SULISTIOWATI | E7: BRI | F7: 065101021315504 | G7: ANGGOTA | H7: FULL - EXISTING | I7: =IF(H7="FULL - EXISTING",5729876,5729876/O7*N7) -> 5729876 | J7: 316368 | K7: 203800 | L7: 1000000 | M7: =L7/O7 -> 50000 | N7: =IFERROR(__xludf.DUMMYFUNCTION("VLOOKUP(C7,IMPORTRANGE(""https://docs.google.com/spreadsheets/d/1ZLN5T8y7NSBIP1rvSj6TTUR_vTQbRwUKSt8zZJ_EfE4/edit?gid=461094331#gid=461094331"",""SCHEDULE_SDT_JAN26""),35,0)"),20) -> 20 | O7: =IFERROR(__xludf.DUMMYFUNCTION("VLOOKUP(C7,IMPORTRANGE(""https://docs.google.com/spreadsheets/d/1ZLN5T8y7NSBIP1rvSj6TTUR_vTQbRwUKSt8zZJ_EfE4/edit?gid=461094331#gid=461094331"",""SCHEDULE_SDT_JAN26""),34,0)"),20) -> 20 | P7: =M7*N7 -> 1000000 | R7: =I7+J7+K7+L7 -> 7250044 | S7: =I7+J7+K7+L7 -> 7250044 | T7: =IF(R7-S7<0,R7-S7,0) -> 0 | U7: 250000 | V7: =IFERROR(__xludf.DUMMYFUNCTION("VLOOKUP(C7,IMPORTRANGE(""https://docs.google.com/spreadsheets/d/1ZLN5T8y7NSBIP1rvSj6TTUR_vTQbRwUKSt8zZJ_EfE4/edit?gid=461094331#gid=461094331"",""SCHEDULE_SDT_JAN26""),36,0)"),0) -> 0 | W7: =U7*V7 -> 0 | X7: 0 | Y7: =I7+J7+K7+P7+W7+X7 -> 7250044 | Z7: =IFERROR(__xludf.DUMMYFUNCTION("VLOOKUP(C7,IMPORTRANGE(""https://docs.google.com/spreadsheets/d/1ZLN5T8y7NSBIP1rvSj6TTUR_vTQbRwUKSt8zZJ_EfE4/edit?gid=461094331#gid=461094331"",""SCHEDULE_SDT_JAN26""),38,0)+VLOOKUP(C7,IMPORTRANGE(""https://docs.google.com/spreadsheets/d/1ZLN5T8y7NSBIP1rv"&"Sj6TTUR_vTQbRwUKSt8zZJ_EfE4/edit?gid=461094331#gid=461094331"",""SCHEDULE_SDT_JAN26""),39,0)"),0) -> 0 | AA7: =IFERROR(__xludf.DUMMYFUNCTION("VLOOKUP(C7,IMPORTRANGE(""https://docs.google.com/spreadsheets/d/1ZLN5T8y7NSBIP1rvSj6TTUR_vTQbRwUKSt8zZJ_EfE4/edit?gid=461094331#gid=461094331"",""SCHEDULE_SDT_JAN26""),40,0)"),0) -> 0 | AB7: =IFERROR(__xludf.DUMMYFUNCTION("VLOOKUP(C7,IMPORTRANGE(""https://docs.google.com/spreadsheets/d/1ZLN5T8y7NSBIP1rvSj6TTUR_vTQbRwUKSt8zZJ_EfE4/edit?gid=461094331#gid=461094331"",""SCHEDULE_SDT_JAN26""),41,0)"),0) -> 0 | AC7: =IFERROR(__xludf.DUMMYFUNCTION("VLOOKUP(C7,IMPORTRANGE(""https://docs.google.com/spreadsheets/d/1ZLN5T8y7NSBIP1rvSj6TTUR_vTQbRwUKSt8zZJ_EfE4/edit?gid=461094331#gid=461094331"",""SCHEDULE_SDT_JAN26""),42,0)"),0) -> 0 | AD7: =IFERROR(__xludf.DUMMYFUNCTION("VLOOKUP(C7,IMPORTRANGE(""https://docs.google.com/spreadsheets/d/1ZLN5T8y7NSBIP1rvSj6TTUR_vTQbRwUKSt8zZJ_EfE4/edit?gid=461094331#gid=461094331"",""SCHEDULE_SDT_JAN26""),43,0)"),0) -> 0 | AE7: =U7*(Z7+AA7+AD7+(AC7)) -> 0 | AF7: 468468 | AG7: 253500 | AH7: 0 | AI7: 0 | AJ7: 0 | AK7: =AI7-AJ7 -> 0 | AL7: 0 | AM7: =AE7+AF7+AG7+AH7+AJ7+AL7 -> 721968 | AN7: =Y7-AM7 -> 6528076 | AO7: =BE7 -> 34950.062 | AP7: =AN7-AO7 -> 6493125.9 | AQ7: =AP7-X7 -> 6493125.9 | AR7: =IF(AQ7>0,ROUND(AQ7,-2),0) -> 6493100 | AT7: K/3 | AU7: C | AV7: =I7 -> 5729876 | AW7: =P7 -> 1000000 | AX7: =W7 -> 0 | AY7: 0 | AZ7: =IF(J7=0,0,AV7*0.24%) -> 13751.702 | BA7: =IF(J7=0,0,AV7*0.3%) -> 17189.628 | BB7: =IF(K7=0,0,AV7*4%) -> 229195.04 | BC7: =SUM(AV7:BB7) -> 6990012.4 | BD7: =IF(AU7="C",VLOOKUP(BC7,TER!$J$4:$L$50,3,TRUE),IF(AU7="B",VLOOKUP(BC7,TER!$F$4:$H$50,3,TRUE),IF(AU7="A",VLOOKUP(BC7,TER!$B$4:$D$50,3,TRUE),"ERROR"))) -> 0.005 | BE7: =BC7*BD7 -> 34950.062
B8: 3 | C8: 5316012208000001 | D8: OKTAVIANUS DAE | E8: BRI | F8: 065101021360509 | G8: ANGGOTA | H8: FULL - EXISTING | I8: =IF(H8="FULL - EXISTING",5729876,5729876/O8*N8) -> 5729876 | J8: 316368 | K8: 203800 | L8: 200000 | M8: =L8/O8 -> 10000 | N8: =IFERROR(__xludf.DUMMYFUNCTION("VLOOKUP(C8,IMPORTRANGE(""https://docs.google.com/spreadsheets/d/1ZLN5T8y7NSBIP1rvSj6TTUR_vTQbRwUKSt8zZJ_EfE4/edit?gid=461094331#gid=461094331"",""SCHEDULE_SDT_JAN26""),35,0)"),20) -> 20 | O8: =IFERROR(__xludf.DUMMYFUNCTION("VLOOKUP(C8,IMPORTRANGE(""https://docs.google.com/spreadsheets/d/1ZLN5T8y7NSBIP1rvSj6TTUR_vTQbRwUKSt8zZJ_EfE4/edit?gid=461094331#gid=461094331"",""SCHEDULE_SDT_JAN26""),34,0)"),20) -> 20 | P8: =M8*N8 -> 200000 | R8: =I8+J8+K8+L8 -> 6450044 | S8: =I8+J8+K8+L8 -> 6450044 | T8: =IF(R8-S8<0,R8-S8,0) -> 0 | U8: 250000 | V8: =IFERROR(__xludf.DUMMYFUNCTION("VLOOKUP(C8,IMPORTRANGE(""https://docs.google.com/spreadsheets/d/1ZLN5T8y7NSBIP1rvSj6TTUR_vTQbRwUKSt8zZJ_EfE4/edit?gid=461094331#gid=461094331"",""SCHEDULE_SDT_JAN26""),36,0)"),2) -> 2 | W8: =U8*V8 -> 500000 | X8: 0 | Y8: =I8+J8+K8+P8+W8+X8 -> 6950044 | Z8: =IFERROR(__xludf.DUMMYFUNCTION("VLOOKUP(C8,IMPORTRANGE(""https://docs.google.com/spreadsheets/d/1ZLN5T8y7NSBIP1rvSj6TTUR_vTQbRwUKSt8zZJ_EfE4/edit?gid=461094331#gid=461094331"",""SCHEDULE_SDT_JAN26""),38,0)+VLOOKUP(C8,IMPORTRANGE(""https://docs.google.com/spreadsheets/d/1ZLN5T8y7NSBIP1rv"&"Sj6TTUR_vTQbRwUKSt8zZJ_EfE4/edit?gid=461094331#gid=461094331"",""SCHEDULE_SDT_JAN26""),39,0)"),0) -> 0 | AA8: =IFERROR(__xludf.DUMMYFUNCTION("VLOOKUP(C8,IMPORTRANGE(""https://docs.google.com/spreadsheets/d/1ZLN5T8y7NSBIP1rvSj6TTUR_vTQbRwUKSt8zZJ_EfE4/edit?gid=461094331#gid=461094331"",""SCHEDULE_SDT_JAN26""),40,0)"),0) -> 0 | AB8: =IFERROR(__xludf.DUMMYFUNCTION("VLOOKUP(C8,IMPORTRANGE(""https://docs.google.com/spreadsheets/d/1ZLN5T8y7NSBIP1rvSj6TTUR_vTQbRwUKSt8zZJ_EfE4/edit?gid=461094331#gid=461094331"",""SCHEDULE_SDT_JAN26""),41,0)"),0) -> 0 | AC8: =IFERROR(__xludf.DUMMYFUNCTION("VLOOKUP(C8,IMPORTRANGE(""https://docs.google.com/spreadsheets/d/1ZLN5T8y7NSBIP1rvSj6TTUR_vTQbRwUKSt8zZJ_EfE4/edit?gid=461094331#gid=461094331"",""SCHEDULE_SDT_JAN26""),42,0)"),0) -> 0 | AD8: =IFERROR(__xludf.DUMMYFUNCTION("VLOOKUP(C8,IMPORTRANGE(""https://docs.google.com/spreadsheets/d/1ZLN5T8y7NSBIP1rvSj6TTUR_vTQbRwUKSt8zZJ_EfE4/edit?gid=461094331#gid=461094331"",""SCHEDULE_SDT_JAN26""),43,0)"),0) -> 0 | AE8: =U8*(Z8+AA8+AD8+(AC8)) -> 0 | AF8: 468468 | AG8: 253500 | AH8: 0 | AI8: 0 | AJ8: 0 | AK8: =AI8-AJ8 -> 0 | AL8: 0 | AM8: =AE8+AF8+AG8+AH8+AJ8+AL8 -> 721968 | AN8: =Y8-AM8 -> 6228076 | AO8: =BE8 -> 66900.124 | AP8: =AN8-AO8 -> 6161175.9 | AQ8: =AP8-X8 -> 6161175.9 | AR8: =IF(AQ8>0,ROUND(AQ8,-2),0) -> 6161200 | AT8: TK/0 | AU8: A | AV8: =I8 -> 5729876 | AW8: =P8 -> 200000 | AX8: =W8 -> 500000 | AY8: 0 | AZ8: =IF(J8=0,0,AV8*0.24%) -> 13751.702 | BA8: =IF(J8=0,0,AV8*0.3%) -> 17189.628 | BB8: =IF(K8=0,0,AV8*4%) -> 229195.04 | BC8: =SUM(AV8:BB8) -> 6690012.4 | BD8: =IF(AU8="C",VLOOKUP(BC8,TER!$J$4:$L$50,3,TRUE),IF(AU8="B",VLOOKUP(BC8,TER!$F$4:$H$50,3,TRUE),IF(AU8="A",VLOOKUP(BC8,TER!$B$4:$D$50,3,TRUE),"ERROR"))) -> 0.01 | BE8: =BC8*BD8 -> 66900.124
B9: 4 | C9: 1801080909010004 | D9: RIAN RONALDO | E9: BRI | F9: 065101021317506 | G9: ANGGOTA | H9: FULL - EXISTING | I9: =IF(H9="FULL - EXISTING",5729876,5729876/O9*N9) -> 5729876 | J9: 316368 | K9: 203800 | L9: 200000 | M9: =L9/O9 -> 9523.8095 | N9: =IFERROR(__xludf.DUMMYFUNCTION("VLOOKUP(C9,IMPORTRANGE(""https://docs.google.com/spreadsheets/d/1ZLN5T8y7NSBIP1rvSj6TTUR_vTQbRwUKSt8zZJ_EfE4/edit?gid=461094331#gid=461094331"",""SCHEDULE_SDT_JAN26""),35,0)"),20) -> 20 | O9: =IFERROR(__xludf.DUMMYFUNCTION("VLOOKUP(C9,IMPORTRANGE(""https://docs.google.com/spreadsheets/d/1ZLN5T8y7NSBIP1rvSj6TTUR_vTQbRwUKSt8zZJ_EfE4/edit?gid=461094331#gid=461094331"",""SCHEDULE_SDT_JAN26""),34,0)"),21) -> 21 | P9: =M9*N9 -> 190476.19 | R9: =I9+J9+K9+L9 -> 6450044 | S9: =I9+J9+K9+L9 -> 6450044 | T9: =IF(R9-S9<0,R9-S9,0) -> 0 | U9: 250000 | V9: =IFERROR(__xludf.DUMMYFUNCTION("VLOOKUP(C9,IMPORTRANGE(""https://docs.google.com/spreadsheets/d/1ZLN5T8y7NSBIP1rvSj6TTUR_vTQbRwUKSt8zZJ_EfE4/edit?gid=461094331#gid=461094331"",""SCHEDULE_SDT_JAN26""),36,0)"),2) -> 2 | W9: =U9*V9 -> 500000 | X9: 0 | Y9: =I9+J9+K9+P9+W9+X9 -> 6940520.2 | Z9: =IFERROR(__xludf.DUMMYFUNCTION("VLOOKUP(C9,IMPORTRANGE(""https://docs.google.com/spreadsheets/d/1ZLN5T8y7NSBIP1rvSj6TTUR_vTQbRwUKSt8zZJ_EfE4/edit?gid=461094331#gid=461094331"",""SCHEDULE_SDT_JAN26""),38,0)+VLOOKUP(C9,IMPORTRANGE(""https://docs.google.com/spreadsheets/d/1ZLN5T8y7NSBIP1rv"&"Sj6TTUR_vTQbRwUKSt8zZJ_EfE4/edit?gid=461094331#gid=461094331"",""SCHEDULE_SDT_JAN26""),39,0)"),0) -> 0 | AA9: =IFERROR(__xludf.DUMMYFUNCTION("VLOOKUP(C9,IMPORTRANGE(""https://docs.google.com/spreadsheets/d/1ZLN5T8y7NSBIP1rvSj6TTUR_vTQbRwUKSt8zZJ_EfE4/edit?gid=461094331#gid=461094331"",""SCHEDULE_SDT_JAN26""),40,0)"),1) -> 1 | AB9: =IFERROR(__xludf.DUMMYFUNCTION("VLOOKUP(C9,IMPORTRANGE(""https://docs.google.com/spreadsheets/d/1ZLN5T8y7NSBIP1rvSj6TTUR_vTQbRwUKSt8zZJ_EfE4/edit?gid=461094331#gid=461094331"",""SCHEDULE_SDT_JAN26""),41,0)"),0) -> 0 | AC9: =IFERROR(__xludf.DUMMYFUNCTION("VLOOKUP(C9,IMPORTRANGE(""https://docs.google.com/spreadsheets/d/1ZLN5T8y7NSBIP1rvSj6TTUR_vTQbRwUKSt8zZJ_EfE4/edit?gid=461094331#gid=461094331"",""SCHEDULE_SDT_JAN26""),42,0)"),0) -> 0 | AD9: =IFERROR(__xludf.DUMMYFUNCTION("VLOOKUP(C9,IMPORTRANGE(""https://docs.google.com/spreadsheets/d/1ZLN5T8y7NSBIP1rvSj6TTUR_vTQbRwUKSt8zZJ_EfE4/edit?gid=461094331#gid=461094331"",""SCHEDULE_SDT_JAN26""),43,0)"),0) -> 0 | AE9: =U9*(Z9+AA9+AD9+(AC9)) -> 250000 | AF9: 468468 | AG9: 253500 | AH9: 0 | AI9: 0 | AJ9: 0 | AK9: =AI9-AJ9 -> 0 | AL9: 0 | AM9: =AE9+AF9+AG9+AH9+AJ9+AL9 -> 971968 | AN9: =Y9-AM9 -> 5968552.2 | AO9: =BE9 -> 66804.886 | AP9: =AN9-AO9 -> 5901747.3 | AQ9: =AP9-X9 -> 5901747.3 | AR9: =IF(AQ9>0,ROUND(AQ9,-2),0) -> 5901700 | AT9: TK/0 | AU9: A | AV9: =I9 -> 5729876 | AW9: =P9 -> 190476.19 | AX9: =W9 -> 500000 | AY9: 0 | AZ9: =IF(J9=0,0,AV9*0.24%) -> 13751.702 | BA9: =IF(J9=0,0,AV9*0.3%) -> 17189.628 | BB9: =IF(K9=0,0,AV9*4%) -> 229195.04 | BC9: =SUM(AV9:BB9) -> 6680488.6 | BD9: =IF(AU9="C",VLOOKUP(BC9,TER!$J$4:$L$50,3,TRUE),IF(AU9="B",VLOOKUP(BC9,TER!$F$4:$H$50,3,TRUE),IF(AU9="A",VLOOKUP(BC9,TER!$B$4:$D$50,3,TRUE),"ERROR"))) -> 0.01 | BE9: =BC9*BD9 -> 66804.886
B10: 5 | C10: 3603170407870014 | D10: YUSIRMAN | E10: BRI | F10: 065101021319508 | G10: ANGGOTA | H10: FULL - EXISTING | I10: =IF(H10="FULL - EXISTING",5729876,5729876/O10*N10) -> 5729876 | J10: 316368 | K10: 203800 | L10: 200000 | M10: =L10/O10 -> 9523.8095 | N10: =IFERROR(__xludf.DUMMYFUNCTION("VLOOKUP(C10,IMPORTRANGE(""https://docs.google.com/spreadsheets/d/1ZLN5T8y7NSBIP1rvSj6TTUR_vTQbRwUKSt8zZJ_EfE4/edit?gid=461094331#gid=461094331"",""SCHEDULE_SDT_JAN26""),35,0)"),21) -> 21 | O10: =IFERROR(__xludf.DUMMYFUNCTION("VLOOKUP(C10,IMPORTRANGE(""https://docs.google.com/spreadsheets/d/1ZLN5T8y7NSBIP1rvSj6TTUR_vTQbRwUKSt8zZJ_EfE4/edit?gid=461094331#gid=461094331"",""SCHEDULE_SDT_JAN26""),34,0)"),21) -> 21 | P10: =M10*N10 -> 200000 | R10: =I10+J10+K10+L10 -> 6450044 | S10: =I10+J10+K10+L10 -> 6450044 | T10: =IF(R10-S10<0,R10-S10,0) -> 0 | U10: 250000 | V10: =IFERROR(__xludf.DUMMYFUNCTION("VLOOKUP(C10,IMPORTRANGE(""https://docs.google.com/spreadsheets/d/1ZLN5T8y7NSBIP1rvSj6TTUR_vTQbRwUKSt8zZJ_EfE4/edit?gid=461094331#gid=461094331"",""SCHEDULE_SDT_JAN26""),36,0)"),2) -> 2 | W10: =U10*V10 -> 500000 | X10: 0 | Y10: =I10+J10+K10+P10+W10+X10 -> 6950044 | Z10: =IFERROR(__xludf.DUMMYFUNCTION("VLOOKUP(C10,IMPORTRANGE(""https://docs.google.com/spreadsheets/d/1ZLN5T8y7NSBIP1rvSj6TTUR_vTQbRwUKSt8zZJ_EfE4/edit?gid=461094331#gid=461094331"",""SCHEDULE_SDT_JAN26""),38,0)+VLOOKUP(C10,IMPORTRANGE(""https://docs.google.com/spreadsheets/d/1ZLN5T8y7NSBIP1"&"rvSj6TTUR_vTQbRwUKSt8zZJ_EfE4/edit?gid=461094331#gid=461094331"",""SCHEDULE_SDT_JAN26""),39,0)"),0) -> 0 | AA10: =IFERROR(__xludf.DUMMYFUNCTION("VLOOKUP(C10,IMPORTRANGE(""https://docs.google.com/spreadsheets/d/1ZLN5T8y7NSBIP1rvSj6TTUR_vTQbRwUKSt8zZJ_EfE4/edit?gid=461094331#gid=461094331"",""SCHEDULE_SDT_JAN26""),40,0)"),0) -> 0 | AB10: =IFERROR(__xludf.DUMMYFUNCTION("VLOOKUP(C10,IMPORTRANGE(""https://docs.google.com/spreadsheets/d/1ZLN5T8y7NSBIP1rvSj6TTUR_vTQbRwUKSt8zZJ_EfE4/edit?gid=461094331#gid=461094331"",""SCHEDULE_SDT_JAN26""),41,0)"),0) -> 0 | AC10: =IFERROR(__xludf.DUMMYFUNCTION("VLOOKUP(C10,IMPORTRANGE(""https://docs.google.com/spreadsheets/d/1ZLN5T8y7NSBIP1rvSj6TTUR_vTQbRwUKSt8zZJ_EfE4/edit?gid=461094331#gid=461094331"",""SCHEDULE_SDT_JAN26""),42,0)"),0) -> 0 | AD10: =IFERROR(__xludf.DUMMYFUNCTION("VLOOKUP(C10,IMPORTRANGE(""https://docs.google.com/spreadsheets/d/1ZLN5T8y7NSBIP1rvSj6TTUR_vTQbRwUKSt8zZJ_EfE4/edit?gid=461094331#gid=461094331"",""SCHEDULE_SDT_JAN26""),43,0)"),0) -> 0 | AE10: =U10*(Z10+AA10+AD10+(AC10)) -> 0 | AF10: 468468 | AG10: 253500 | AH10: 0 | AI10: 0 | AJ10: 0 | AK10: =AI10-AJ10 -> 0 | AL10: 0 | AM10: =AE10+AF10+AG10+AH10+AJ10+AL10 -> 721968 | AN10: =Y10-AM10 -> 6228076 | AO10: =BE10 -> 66900.124 | AP10: =AN10-AO10 -> 6161175.9 | AQ10: =AP10-X10 -> 6161175.9 | AR10: =IF(AQ10>0,ROUND(AQ10,-2),0) -> 6161200 | AT10: TK/0 | AU10: A | AV10: =I10 -> 5729876 | AW10: =P10 -> 200000 | AX10: =W10 -> 500000 | AY10: 0 | AZ10: =IF(J10=0,0,AV10*0.24%) -> 13751.702 | BA10: =IF(J10=0,0,AV10*0.3%) -> 17189.628 | BB10: =IF(K10=0,0,AV10*4%) -> 229195.04 | BC10: =SUM(AV10:BB10) -> 6690012.4 | BD10: =IF(AU10="C",VLOOKUP(BC10,TER!$J$4:$L$50,3,TRUE),IF(AU10="B",VLOOKUP(BC10,TER!$F$4:$H$50,3,TRUE),IF(AU10="A",VLOOKUP(BC10,TER!$B$4:$D$50,3,TRUE),"ERROR"))) -> 0.01 | BE10: =BC10*BD10 -> 66900.124
B11: 6 | C11: 3213091812990001 | D11: KRISMA HIDAYAT | E11: BRI | F11: 065101021320509 | G11: ANGGOTA | H11: FULL - EXISTING | I11: =IF(H11="FULL - EXISTING",5729876,5729876/O11*N11) -> 5729876 | J11: 316368 | K11: 203800 | L11: 200000 | M11: =L11/O11 -> 9523.8095 | N11: =IFERROR(__xludf.DUMMYFUNCTION("VLOOKUP(C11,IMPORTRANGE(""https://docs.google.com/spreadsheets/d/1ZLN5T8y7NSBIP1rvSj6TTUR_vTQbRwUKSt8zZJ_EfE4/edit?gid=461094331#gid=461094331"",""SCHEDULE_SDT_JAN26""),35,0)"),21) -> 21 | O11: =IFERROR(__xludf.DUMMYFUNCTION("VLOOKUP(C11,IMPORTRANGE(""https://docs.google.com/spreadsheets/d/1ZLN5T8y7NSBIP1rvSj6TTUR_vTQbRwUKSt8zZJ_EfE4/edit?gid=461094331#gid=461094331"",""SCHEDULE_SDT_JAN26""),34,0)"),21) -> 21 | P11: =M11*N11 -> 200000 | R11: =I11+J11+K11+L11 -> 6450044 | S11: =I11+J11+K11+L11 -> 6450044 | T11: =IF(R11-S11<0,R11-S11,0) -> 0 | U11: 250000 | V11: =IFERROR(__xludf.DUMMYFUNCTION("VLOOKUP(C11,IMPORTRANGE(""https://docs.google.com/spreadsheets/d/1ZLN5T8y7NSBIP1rvSj6TTUR_vTQbRwUKSt8zZJ_EfE4/edit?gid=461094331#gid=461094331"",""SCHEDULE_SDT_JAN26""),36,0)"),0) -> 0 | W11: =U11*V11 -> 0 | X11: 0 | Y11: =I11+J11+K11+P11+W11+X11 -> 6450044 | Z11: =IFERROR(__xludf.DUMMYFUNCTION("VLOOKUP(C11,IMPORTRANGE(""https://docs.google.com/spreadsheets/d/1ZLN5T8y7NSBIP1rvSj6TTUR_vTQbRwUKSt8zZJ_EfE4/edit?gid=461094331#gid=461094331"",""SCHEDULE_SDT_JAN26""),38,0)+VLOOKUP(C11,IMPORTRANGE(""https://docs.google.com/spreadsheets/d/1ZLN5T8y7NSBIP1"&"rvSj6TTUR_vTQbRwUKSt8zZJ_EfE4/edit?gid=461094331#gid=461094331"",""SCHEDULE_SDT_JAN26""),39,0)"),0) -> 0 | AA11: =IFERROR(__xludf.DUMMYFUNCTION("VLOOKUP(C11,IMPORTRANGE(""https://docs.google.com/spreadsheets/d/1ZLN5T8y7NSBIP1rvSj6TTUR_vTQbRwUKSt8zZJ_EfE4/edit?gid=461094331#gid=461094331"",""SCHEDULE_SDT_JAN26""),40,0)"),0) -> 0 | AB11: =IFERROR(__xludf.DUMMYFUNCTION("VLOOKUP(C11,IMPORTRANGE(""https://docs.google.com/spreadsheets/d/1ZLN5T8y7NSBIP1rvSj6TTUR_vTQbRwUKSt8zZJ_EfE4/edit?gid=461094331#gid=461094331"",""SCHEDULE_SDT_JAN26""),41,0)"),0) -> 0 | AC11: =IFERROR(__xludf.DUMMYFUNCTION("VLOOKUP(C11,IMPORTRANGE(""https://docs.google.com/spreadsheets/d/1ZLN5T8y7NSBIP1rvSj6TTUR_vTQbRwUKSt8zZJ_EfE4/edit?gid=461094331#gid=461094331"",""SCHEDULE_SDT_JAN26""),42,0)"),0) -> 0 | AD11: =IFERROR(__xludf.DUMMYFUNCTION("VLOOKUP(C11,IMPORTRANGE(""https://docs.google.com/spreadsheets/d/1ZLN5T8y7NSBIP1rvSj6TTUR_vTQbRwUKSt8zZJ_EfE4/edit?gid=461094331#gid=461094331"",""SCHEDULE_SDT_JAN26""),43,0)"),0) -> 0 | AE11: =U11*(Z11+AA11+AD11+(AC11)) -> 0 | AF11: 468468 | AG11: 253500 | AH11: 0 | AI11: 0 | AJ11: 0 | AK11: =AI11-AJ11 -> 0 | AL11: 0 | AM11: =AE11+AF11+AG11+AH11+AJ11+AL11 -> 721968 | AN11: =Y11-AM11 -> 5728076 | AO11: =BE11 -> 0 | AP11: =AN11-AO11 -> 5728076 | AQ11: =AP11-X11 -> 5728076 | AR11: =IF(AQ11>0,ROUND(AQ11,-2),0) -> 5728100 | AT11: K/2 | AU11: B | AV11: =I11 -> 5729876 | AW11: =P11 -> 200000 | AX11: =W11 -> 0 | AY11: 0 | AZ11: =IF(J11=0,0,AV11*0.24%) -> 13751.702 | BA11: =IF(J11=0,0,AV11*0.3%) -> 17189.628 | BB11: =IF(K11=0,0,AV11*4%) -> 229195.04 | BC11: =SUM(AV11:BB11) -> 6190012.4 | BD11: =IF(AU11="C",VLOOKUP(BC11,TER!$J$4:$L$50,3,TRUE),IF(AU11="B",VLOOKUP(BC11,TER!$F$4:$H$50,3,TRUE),IF(AU11="A",VLOOKUP(BC11,TER!$B$4:$D$50,3,TRUE),"ERROR"))) -> 0 | BE11: =BC11*BD11 -> 0
B12: 7 | C12: 5308081606970001 | D12: NURDIN DURI | E12: BRI | F12: 065101021322501 | G12: ANGGOTA | H12: FULL - EXISTING | I12: =IF(H12="FULL - EXISTING",5729876,5729876/O12*N12) -> 5729876 | J12: 316368 | K12: 203800 | L12: 100000 | M12: =L12/O12 -> 4761.9048 | N12: =IFERROR(__xludf.DUMMYFUNCTION("VLOOKUP(C12,IMPORTRANGE(""https://docs.google.com/spreadsheets/d/1ZLN5T8y7NSBIP1rvSj6TTUR_vTQbRwUKSt8zZJ_EfE4/edit?gid=461094331#gid=461094331"",""SCHEDULE_SDT_JAN26""),35,0)"),21) -> 21 | O12: =IFERROR(__xludf.DUMMYFUNCTION("VLOOKUP(C12,IMPORTRANGE(""https://docs.google.com/spreadsheets/d/1ZLN5T8y7NSBIP1rvSj6TTUR_vTQbRwUKSt8zZJ_EfE4/edit?gid=461094331#gid=461094331"",""SCHEDULE_SDT_JAN26""),34,0)"),21) -> 21 | P12: =M12*N12 -> 100000 | R12: =I12+J12+K12+L12 -> 6350044 | S12: =I12+J12+K12+L12 -> 6350044 | T12: =IF(R12-S12<0,R12-S12,0) -> 0 | U12: 250000 | V12: =IFERROR(__xludf.DUMMYFUNCTION("VLOOKUP(C12,IMPORTRANGE(""https://docs.google.com/spreadsheets/d/1ZLN5T8y7NSBIP1rvSj6TTUR_vTQbRwUKSt8zZJ_EfE4/edit?gid=461094331#gid=461094331"",""SCHEDULE_SDT_JAN26""),36,0)"),1) -> 1 | W12: =U12*V12 -> 250000 | X12: 0 | Y12: =I12+J12+K12+P12+W12+X12 -> 6600044 | Z12: =IFERROR(__xludf.DUMMYFUNCTION("VLOOKUP(C12,IMPORTRANGE(""https://docs.google.com/spreadsheets/d/1ZLN5T8y7NSBIP1rvSj6TTUR_vTQbRwUKSt8zZJ_EfE4/edit?gid=461094331#gid=461094331"",""SCHEDULE_SDT_JAN26""),38,0)+VLOOKUP(C12,IMPORTRANGE(""https://docs.google.com/spreadsheets/d/1ZLN5T8y7NSBIP1"&"rvSj6TTUR_vTQbRwUKSt8zZJ_EfE4/edit?gid=461094331#gid=461094331"",""SCHEDULE_SDT_JAN26""),39,0)"),0) -> 0 | AA12: =IFERROR(__xludf.DUMMYFUNCTION("VLOOKUP(C12,IMPORTRANGE(""https://docs.google.com/spreadsheets/d/1ZLN5T8y7NSBIP1rvSj6TTUR_vTQbRwUKSt8zZJ_EfE4/edit?gid=461094331#gid=461094331"",""SCHEDULE_SDT_JAN26""),40,0)"),0) -> 0 | AB12: =IFERROR(__xludf.DUMMYFUNCTION("VLOOKUP(C12,IMPORTRANGE(""https://docs.google.com/spreadsheets/d/1ZLN5T8y7NSBIP1rvSj6TTUR_vTQbRwUKSt8zZJ_EfE4/edit?gid=461094331#gid=461094331"",""SCHEDULE_SDT_JAN26""),41,0)"),0) -> 0 | AC12: =IFERROR(__xludf.DUMMYFUNCTION("VLOOKUP(C12,IMPORTRANGE(""https://docs.google.com/spreadsheets/d/1ZLN5T8y7NSBIP1rvSj6TTUR_vTQbRwUKSt8zZJ_EfE4/edit?gid=461094331#gid=461094331"",""SCHEDULE_SDT_JAN26""),42,0)"),0) -> 0 | AD12: =IFERROR(__xludf.DUMMYFUNCTION("VLOOKUP(C12,IMPORTRANGE(""https://docs.google.com/spreadsheets/d/1ZLN5T8y7NSBIP1rvSj6TTUR_vTQbRwUKSt8zZJ_EfE4/edit?gid=461094331#gid=461094331"",""SCHEDULE_SDT_JAN26""),43,0)"),0) -> 0 | AE12: =U12*(Z12+AA12+AD12+(AC12)) -> 0 | AF12: 468468 | AG12: 253500 | AH12: 0 | AI12: 0 | AJ12: 0 | AK12: =AI12-AJ12 -> 0 | AL12: 0 | AM12: =AE12+AF12+AG12+AH12+AJ12+AL12 -> 721968 | AN12: =Y12-AM12 -> 5878076 | AO12: =BE12 -> 63400.124 | AP12: =AN12-AO12 -> 5814675.9 | AQ12: =AP12-X12 -> 5814675.9 | AR12: =IF(AQ12>0,ROUND(AQ12,-2),0) -> 5814700 | AT12: TK/0 | AU12: A | AV12: =I12 -> 5729876 | AW12: =P12 -> 100000 | AX12: =W12 -> 250000 | AY12: 0 | AZ12: =IF(J12=0,0,AV12*0.24%) -> 13751.702 | BA12: =IF(J12=0,0,AV12*0.3%) -> 17189.628 | BB12: =IF(K12=0,0,AV12*4%) -> 229195.04 | BC12: =SUM(AV12:BB12) -> 6340012.4 | BD12: =IF(AU12="C",VLOOKUP(BC12,TER!$J$4:$L$50,3,TRUE),IF(AU12="B",VLOOKUP(BC12,TER!$F$4:$H$50,3,TRUE),IF(AU12="A",VLOOKUP(BC12,TER!$B$4:$D$50,3,TRUE),"ERROR"))) -> 0.01 | BE12: =BC12*BD12 -> 63400.124
B13: 8 | C13: 5316013103980002 | D13: BENYAMIN GOA | E13: BRI | F13: 065101021323507 | G13: ANGGOTA | H13: FULL - EXISTING | I13: =IF(H13="FULL - EXISTING",5729876,5729876/O13*N13) -> 5729876 | J13: 316368 | K13: 203800 | L13: 200000 | M13: =L13/O13 -> 9523.8095 | N13: =IFERROR(__xludf.DUMMYFUNCTION("VLOOKUP(C13,IMPORTRANGE(""https://docs.google.com/spreadsheets/d/1ZLN5T8y7NSBIP1rvSj6TTUR_vTQbRwUKSt8zZJ_EfE4/edit?gid=461094331#gid=461094331"",""SCHEDULE_SDT_JAN26""),35,0)"),21) -> 21 | O13: =IFERROR(__xludf.DUMMYFUNCTION("VLOOKUP(C13,IMPORTRANGE(""https://docs.google.com/spreadsheets/d/1ZLN5T8y7NSBIP1rvSj6TTUR_vTQbRwUKSt8zZJ_EfE4/edit?gid=461094331#gid=461094331"",""SCHEDULE_SDT_JAN26""),34,0)"),21) -> 21 | P13: =M13*N13 -> 200000 | R13: =I13+J13+K13+L13 -> 6450044 | S13: =I13+J13+K13+L13 -> 6450044 | T13: =IF(R13-S13<0,R13-S13,0) -> 0 | U13: 250000 | V13: =IFERROR(__xludf.DUMMYFUNCTION("VLOOKUP(C13,IMPORTRANGE(""https://docs.google.com/spreadsheets/d/1ZLN5T8y7NSBIP1rvSj6TTUR_vTQbRwUKSt8zZJ_EfE4/edit?gid=461094331#gid=461094331"",""SCHEDULE_SDT_JAN26""),36,0)"),1) -> 1 | W13: =U13*V13 -> 250000 | X13: 0 | Y13: =I13+J13+K13+P13+W13+X13 -> 6700044 | Z13: =IFERROR(__xludf.DUMMYFUNCTION("VLOOKUP(C13,IMPORTRANGE(""https://docs.google.com/spreadsheets/d/1ZLN5T8y7NSBIP1rvSj6TTUR_vTQbRwUKSt8zZJ_EfE4/edit?gid=461094331#gid=461094331"",""SCHEDULE_SDT_JAN26""),38,0)+VLOOKUP(C13,IMPORTRANGE(""https://docs.google.com/spreadsheets/d/1ZLN5T8y7NSBIP1"&"rvSj6TTUR_vTQbRwUKSt8zZJ_EfE4/edit?gid=461094331#gid=461094331"",""SCHEDULE_SDT_JAN26""),39,0)"),0) -> 0 | AA13: =IFERROR(__xludf.DUMMYFUNCTION("VLOOKUP(C13,IMPORTRANGE(""https://docs.google.com/spreadsheets/d/1ZLN5T8y7NSBIP1rvSj6TTUR_vTQbRwUKSt8zZJ_EfE4/edit?gid=461094331#gid=461094331"",""SCHEDULE_SDT_JAN26""),40,0)"),0) -> 0 | AB13: =IFERROR(__xludf.DUMMYFUNCTION("VLOOKUP(C13,IMPORTRANGE(""https://docs.google.com/spreadsheets/d/1ZLN5T8y7NSBIP1rvSj6TTUR_vTQbRwUKSt8zZJ_EfE4/edit?gid=461094331#gid=461094331"",""SCHEDULE_SDT_JAN26""),41,0)"),0) -> 0 | AC13: =IFERROR(__xludf.DUMMYFUNCTION("VLOOKUP(C13,IMPORTRANGE(""https://docs.google.com/spreadsheets/d/1ZLN5T8y7NSBIP1rvSj6TTUR_vTQbRwUKSt8zZJ_EfE4/edit?gid=461094331#gid=461094331"",""SCHEDULE_SDT_JAN26""),42,0)"),0) -> 0 | AD13: =IFERROR(__xludf.DUMMYFUNCTION("VLOOKUP(C13,IMPORTRANGE(""https://docs.google.com/spreadsheets/d/1ZLN5T8y7NSBIP1rvSj6TTUR_vTQbRwUKSt8zZJ_EfE4/edit?gid=461094331#gid=461094331"",""SCHEDULE_SDT_JAN26""),43,0)"),0) -> 0 | AE13: =U13*(Z13+AA13+AD13+(AC13)) -> 0 | AF13: 468468 | AG13: 253500 | AH13: 0 | AI13: 0 | AJ13: 0 | AK13: =AI13-AJ13 -> 0 | AL13: 0 | AM13: =AE13+AF13+AG13+AH13+AJ13+AL13 -> 721968 | AN13: =Y13-AM13 -> 5978076 | AO13: =BE13 -> 64400.124 | AP13: =AN13-AO13 -> 5913675.9 | AQ13: =AP13-X13 -> 5913675.9 | AR13: =IF(AQ13>0,ROUND(AQ13,-2),0) -> 5913700 | AT13: TK/0 | AU13: A | AV13: =I13 -> 5729876 | AW13: =P13 -> 200000 | AX13: =W13 -> 250000 | AY13: 0 | AZ13: =IF(J13=0,0,AV13*0.24%) -> 13751.702 | BA13: =IF(J13=0,0,AV13*0.3%) -> 17189.628 | BB13: =IF(K13=0,0,AV13*4%) -> 229195.04 | BC13: =SUM(AV13:BB13) -> 6440012.4 | BD13: =IF(AU13="C",VLOOKUP(BC13,TER!$J$4:$L$50,3,TRUE),IF(AU13="B",VLOOKUP(BC13,TER!$F$4:$H$50,3,TRUE),IF(AU13="A",VLOOKUP(BC13,TER!$B$4:$D$50,3,TRUE),"ERROR"))) -> 0.01 | BE13: =BC13*BD13 -> 64400.124
B14: 9 | C14: 3175062304010010 | D14: ALFIYAN | E14: BRI | F14: 065101021324503 | G14: ANGGOTA | H14: FULL - EXISTING | I14: =IF(H14="FULL - EXISTING",5729876,5729876/O14*N14) -> 5729876 | J14: 316368 | K14: 203800 | L14: 100000 | M14: =L14/O14 -> 4761.9048 | N14: =IFERROR(__xludf.DUMMYFUNCTION("VLOOKUP(C14,IMPORTRANGE(""https://docs.google.com/spreadsheets/d/1ZLN5T8y7NSBIP1rvSj6TTUR_vTQbRwUKSt8zZJ_EfE4/edit?gid=461094331#gid=461094331"",""SCHEDULE_SDT_JAN26""),35,0)"),11) -> 11 | O14: =IFERROR(__xludf.DUMMYFUNCTION("VLOOKUP(C14,IMPORTRANGE(""https://docs.google.com/spreadsheets/d/1ZLN5T8y7NSBIP1rvSj6TTUR_vTQbRwUKSt8zZJ_EfE4/edit?gid=461094331#gid=461094331"",""SCHEDULE_SDT_JAN26""),34,0)"),21) -> 21 | P14: =M14*N14 -> 52380.952 | R14: =I14+J14+K14+L14 -> 6350044 | S14: =I14+J14+K14+L14 -> 6350044 | T14: =IF(R14-S14<0,R14-S14,0) -> 0 | U14: 250000 | V14: =IFERROR(__xludf.DUMMYFUNCTION("VLOOKUP(C14,IMPORTRANGE(""https://docs.google.com/spreadsheets/d/1ZLN5T8y7NSBIP1rvSj6TTUR_vTQbRwUKSt8zZJ_EfE4/edit?gid=461094331#gid=461094331"",""SCHEDULE_SDT_JAN26""),36,0)"),0) -> 0 | W14: =U14*V14 -> 0 | X14: 0 | Y14: =I14+J14+K14+P14+W14+X14 -> 6302425 | Z14: =IFERROR(__xludf.DUMMYFUNCTION("VLOOKUP(C14,IMPORTRANGE(""https://docs.google.com/spreadsheets/d/1ZLN5T8y7NSBIP1rvSj6TTUR_vTQbRwUKSt8zZJ_EfE4/edit?gid=461094331#gid=461094331"",""SCHEDULE_SDT_JAN26""),38,0)+VLOOKUP(C14,IMPORTRANGE(""https://docs.google.com/spreadsheets/d/1ZLN5T8y7NSBIP1"&"rvSj6TTUR_vTQbRwUKSt8zZJ_EfE4/edit?gid=461094331#gid=461094331"",""SCHEDULE_SDT_JAN26""),39,0)"),1) -> 1 | AA14: =IFERROR(__xludf.DUMMYFUNCTION("VLOOKUP(C14,IMPORTRANGE(""https://docs.google.com/spreadsheets/d/1ZLN5T8y7NSBIP1rvSj6TTUR_vTQbRwUKSt8zZJ_EfE4/edit?gid=461094331#gid=461094331"",""SCHEDULE_SDT_JAN26""),40,0)"),4) -> 4 | AB14: =IFERROR(__xludf.DUMMYFUNCTION("VLOOKUP(C14,IMPORTRANGE(""https://docs.google.com/spreadsheets/d/1ZLN5T8y7NSBIP1rvSj6TTUR_vTQbRwUKSt8zZJ_EfE4/edit?gid=461094331#gid=461094331"",""SCHEDULE_SDT_JAN26""),41,0)"),0) -> 0 | AC14: =IFERROR(__xludf.DUMMYFUNCTION("VLOOKUP(C14,IMPORTRANGE(""https://docs.google.com/spreadsheets/d/1ZLN5T8y7NSBIP1rvSj6TTUR_vTQbRwUKSt8zZJ_EfE4/edit?gid=461094331#gid=461094331"",""SCHEDULE_SDT_JAN26""),42,0)"),0) -> 0 | AD14: =IFERROR(__xludf.DUMMYFUNCTION("VLOOKUP(C14,IMPORTRANGE(""https://docs.google.com/spreadsheets/d/1ZLN5T8y7NSBIP1rvSj6TTUR_vTQbRwUKSt8zZJ_EfE4/edit?gid=461094331#gid=461094331"",""SCHEDULE_SDT_JAN26""),43,0)"),0) -> 0 | AE14: =U14*(Z14+AA14+AD14+(AC14)) -> 1250000 | AF14: 468468 | AG14: 253500 | AH14: 1000000 | AI14: 0 | AJ14: 0 | AK14: =AI14-AJ14 -> 0 | AL14: 0 | AM14: =AE14+AF14+AG14+AH14+AJ14+AL14 -> 2971968 | AN14: =Y14-AM14 -> 3330457 | AO14: =BE14 -> 45317.95 | AP14: =AN14-AO14 -> 3285139 | AQ14: =AP14-X14 -> 3285139 | AR14: =IF(AQ14>0,ROUND(AQ14,-2),0) -> 3285100 | AT14: TK/0 | AU14: A | AV14: =I14 -> 5729876 | AW14: =P14 -> 52380.952 | AX14: =W14 -> 0 | AY14: 0 | AZ14: =IF(J14=0,0,AV14*0.24%) -> 13751.702 | BA14: =IF(J14=0,0,AV14*0.3%) -> 17189.628 | BB14: =IF(K14=0,0,AV14*4%) -> 229195.04 | BC14: =SUM(AV14:BB14) -> 6042393.3 | BD14: =IF(AU14="C",VLOOKUP(BC14,TER!$J$4:$L$50,3,TRUE),IF(AU14="B",VLOOKUP(BC14,TER!$F$4:$H$50,3,TRUE),IF(AU14="A",VLOOKUP(BC14,TER!$B$4:$D$50,3,TRUE),"ERROR"))) -> 0.0075 | BE14: =BC14*BD14 -> 45317.95
B15: 10 | C15: 1771041503900005 | D15: RADITYO FIKRI NUGROHO | E15: BRI | F15: 065101021361505 | G15: SHIFT LEADER | H15: FULL - EXISTING | I15: =IF(H15="FULL - EXISTING",5729876,5729876/O15*N15) -> 5729876 | J15: 316368 | K15: 203800 | L15: 2000000 | M15: =L15/O15 -> 95238.095 | N15: =IFERROR(__xludf.DUMMYFUNCTION("VLOOKUP(C15,IMPORTRANGE(""https://docs.google.com/spreadsheets/d/1ZLN5T8y7NSBIP1rvSj6TTUR_vTQbRwUKSt8zZJ_EfE4/edit?gid=461094331#gid=461094331"",""SCHEDULE_SDT_JAN26""),35,0)"),2) -> 2 | O15: =IFERROR(__xludf.DUMMYFUNCTION("VLOOKUP(C15,IMPORTRANGE(""https://docs.google.com/spreadsheets/d/1ZLN5T8y7NSBIP1rvSj6TTUR_vTQbRwUKSt8zZJ_EfE4/edit?gid=461094331#gid=461094331"",""SCHEDULE_SDT_JAN26""),34,0)"),21) -> 21 | P15: =M15*N15 -> 190476.19 | R15: =I15+J15+K15+L15 -> 8250044 | S15: =I15+J15+K15+L15 -> 8250044 | T15: =IF(R15-S15<0,R15-S15,0) -> 0 | U15: 250000 | V15: =IFERROR(__xludf.DUMMYFUNCTION("VLOOKUP(C15,IMPORTRANGE(""https://docs.google.com/spreadsheets/d/1ZLN5T8y7NSBIP1rvSj6TTUR_vTQbRwUKSt8zZJ_EfE4/edit?gid=461094331#gid=461094331"",""SCHEDULE_SDT_JAN26""),36,0)"),0) -> 0 | W15: =U15*V15 -> 0 | X15: 0 | Y15: =I15+J15+K15+P15+W15+X15 -> 6440520.2 | Z15: =IFERROR(__xludf.DUMMYFUNCTION("VLOOKUP(C15,IMPORTRANGE(""https://docs.google.com/spreadsheets/d/1ZLN5T8y7NSBIP1rvSj6TTUR_vTQbRwUKSt8zZJ_EfE4/edit?gid=461094331#gid=461094331"",""SCHEDULE_SDT_JAN26""),38,0)+VLOOKUP(C15,IMPORTRANGE(""https://docs.google.com/spreadsheets/d/1ZLN5T8y7NSBIP1"&"rvSj6TTUR_vTQbRwUKSt8zZJ_EfE4/edit?gid=461094331#gid=461094331"",""SCHEDULE_SDT_JAN26""),39,0)"),0) -> 0 | AA15: =IFERROR(__xludf.DUMMYFUNCTION("VLOOKUP(C15,IMPORTRANGE(""https://docs.google.com/spreadsheets/d/1ZLN5T8y7NSBIP1rvSj6TTUR_vTQbRwUKSt8zZJ_EfE4/edit?gid=461094331#gid=461094331"",""SCHEDULE_SDT_JAN26""),40,0)"),0) -> 0 | AB15: =IFERROR(__xludf.DUMMYFUNCTION("VLOOKUP(C15,IMPORTRANGE(""https://docs.google.com/spreadsheets/d/1ZLN5T8y7NSBIP1rvSj6TTUR_vTQbRwUKSt8zZJ_EfE4/edit?gid=461094331#gid=461094331"",""SCHEDULE_SDT_JAN26""),41,0)"),0) -> 0 | AC15: =IFERROR(__xludf.DUMMYFUNCTION("VLOOKUP(C15,IMPORTRANGE(""https://docs.google.com/spreadsheets/d/1ZLN5T8y7NSBIP1rvSj6TTUR_vTQbRwUKSt8zZJ_EfE4/edit?gid=461094331#gid=461094331"",""SCHEDULE_SDT_JAN26""),42,0)"),0) -> 0 | AD15: =IFERROR(__xludf.DUMMYFUNCTION("VLOOKUP(C15,IMPORTRANGE(""https://docs.google.com/spreadsheets/d/1ZLN5T8y7NSBIP1rvSj6TTUR_vTQbRwUKSt8zZJ_EfE4/edit?gid=461094331#gid=461094331"",""SCHEDULE_SDT_JAN26""),43,0)"),0) -> 0 | AE15: =U15*(Z15+AA15+AD15+(AC15)) -> 0 | AF15: 468468 | AG15: 253500 | AH15: 0 | AI15: 0 | AJ15: 0 | AK15: =AI15-AJ15 -> 0 | AL15: 0 | AM15: =AE15+AF15+AG15+AH15+AJ15+AL15 -> 721968 | AN15: =Y15-AM15 -> 5718552.2 | AO15: =BE15 -> 46353.664 | AP15: =AN15-AO15 -> 5672198.5 | AQ15: =AP15-X15 -> 5672198.5 | AR15: =IF(AQ15>0,ROUND(AQ15,-2),0) -> 5672200 | AT15: TK/0 | AU15: A | AV15: =I15 -> 5729876 | AW15: =P15 -> 190476.19 | AX15: =W15 -> 0 | AY15: 0 | AZ15: =IF(J15=0,0,AV15*0.24%) -> 13751.702 | BA15: =IF(J15=0,0,AV15*0.3%) -> 17189.628 | BB15: =IF(K15=0,0,AV15*4%) -> 229195.04 | BC15: =SUM(AV15:BB15) -> 6180488.6 | BD15: =IF(AU15="C",VLOOKUP(BC15,TER!$J$4:$L$50,3,TRUE),IF(AU15="B",VLOOKUP(BC15,TER!$F$4:$H$50,3,TRUE),IF(AU15="A",VLOOKUP(BC15,TER!$B$4:$D$50,3,TRUE),"ERROR"))) -> 0.0075 | BE15: =BC15*BD15 -> 46353.664
B16: 10 A | C16: 1771041503900005 A | D16: RADITYO FIKRI NUGROHO | E16: BRI | F16: 065101021361505 | G16: PLT CHIEF | H16: PRORATE - MASUK | L16: 2750000 | M16: =L16/O16 -> 137500 | N16: =IFERROR(__xludf.DUMMYFUNCTION("VLOOKUP(C16,IMPORTRANGE(""https://docs.google.com/spreadsheets/d/1ZLN5T8y7NSBIP1rvSj6TTUR_vTQbRwUKSt8zZJ_EfE4/edit?gid=461094331#gid=461094331"",""SCHEDULE_SDT_JAN26""),35,0)"),19) -> 19 | O16: 20 | P16: =M16*N16 -> 2612500 | R16: =I16+J16+K16+L16 -> 2750000 | S16: =I16+J16+K16+L16 -> 2750000 | T16: =IF(R16-S16<0,R16-S16,0) -> 0 | U16: 250000 | V16: =IFERROR(__xludf.DUMMYFUNCTION("VLOOKUP(C16,IMPORTRANGE(""https://docs.google.com/spreadsheets/d/1ZLN5T8y7NSBIP1rvSj6TTUR_vTQbRwUKSt8zZJ_EfE4/edit?gid=461094331#gid=461094331"",""SCHEDULE_SDT_JAN26""),36,0)"),0) -> 0 | W16: =U16*V16 -> 0 | X16: 0 | Y16: =I16+J16+K16+P16+W16+X16 -> 2612500 | Z16: =IFERROR(__xludf.DUMMYFUNCTION("VLOOKUP(C16,IMPORTRANGE(""https://docs.google.com/spreadsheets/d/1ZLN5T8y7NSBIP1rvSj6TTUR_vTQbRwUKSt8zZJ_EfE4/edit?gid=461094331#gid=461094331"",""SCHEDULE_SDT_JAN26""),38,0)+VLOOKUP(C16,IMPORTRANGE(""https://docs.google.com/spreadsheets/d/1ZLN5T8y7NSBIP1"&"rvSj6TTUR_vTQbRwUKSt8zZJ_EfE4/edit?gid=461094331#gid=461094331"",""SCHEDULE_SDT_JAN26""),39,0)"),0) -> 0 | AA16: =IFERROR(__xludf.DUMMYFUNCTION("VLOOKUP(C16,IMPORTRANGE(""https://docs.google.com/spreadsheets/d/1ZLN5T8y7NSBIP1rvSj6TTUR_vTQbRwUKSt8zZJ_EfE4/edit?gid=461094331#gid=461094331"",""SCHEDULE_SDT_JAN26""),40,0)"),0) -> 0 | AB16: =IFERROR(__xludf.DUMMYFUNCTION("VLOOKUP(C16,IMPORTRANGE(""https://docs.google.com/spreadsheets/d/1ZLN5T8y7NSBIP1rvSj6TTUR_vTQbRwUKSt8zZJ_EfE4/edit?gid=461094331#gid=461094331"",""SCHEDULE_SDT_JAN26""),41,0)"),0) -> 0 | AC16: =IFERROR(__xludf.DUMMYFUNCTION("VLOOKUP(C16,IMPORTRANGE(""https://docs.google.com/spreadsheets/d/1ZLN5T8y7NSBIP1rvSj6TTUR_vTQbRwUKSt8zZJ_EfE4/edit?gid=461094331#gid=461094331"",""SCHEDULE_SDT_JAN26""),42,0)"),0) -> 0 | AD16: =IFERROR(__xludf.DUMMYFUNCTION("VLOOKUP(C16,IMPORTRANGE(""https://docs.google.com/spreadsheets/d/1ZLN5T8y7NSBIP1rvSj6TTUR_vTQbRwUKSt8zZJ_EfE4/edit?gid=461094331#gid=461094331"",""SCHEDULE_SDT_JAN26""),43,0)"),0) -> 0 | AE16: =U16*(Z16+AA16+AD16+(AC16)) -> 0 | AH16: 0 | AI16: 0 | AJ16: 0 | AK16: =AI16-AJ16 -> 0 | AL16: 0 | AM16: =AE16+AF16+AG16+AH16+AJ16+AL16 -> 0 | AN16: =Y16-AM16 -> 2612500 | AO16: =BE16 -> 0 | AP16: =AN16-AO16 -> 2612500 | AQ16: =AP16-X16 -> 2612500 | AR16: =IF(AQ16>0,ROUND(AQ16,-2),0) -> 2612500
B17: 11 | C17: 1801071805870002 | D17: SARDA | E17: BRI | F17: 065101021325509 | G17: ANGGOTA | H17: FULL - EXISTING | I17: =IF(H17="FULL - EXISTING",5729876,5729876/O17*N17) -> 5729876 | J17: 316368 | K17: 203800 | L17: 1000000 | M17: =L17/O17 -> 47619.048 | N17: =IFERROR(__xludf.DUMMYFUNCTION("VLOOKUP(C17,IMPORTRANGE(""https://docs.google.com/spreadsheets/d/1ZLN5T8y7NSBIP1rvSj6TTUR_vTQbRwUKSt8zZJ_EfE4/edit?gid=461094331#gid=461094331"",""SCHEDULE_SDT_JAN26""),35,0)"),21) -> 21 | O17: =IFERROR(__xludf.DUMMYFUNCTION("VLOOKUP(C17,IMPORTRANGE(""https://docs.google.com/spreadsheets/d/1ZLN5T8y7NSBIP1rvSj6TTUR_vTQbRwUKSt8zZJ_EfE4/edit?gid=461094331#gid=461094331"",""SCHEDULE_SDT_JAN26""),34,0)"),21) -> 21 | P17: =M17*N17 -> 1000000 | R17: =I17+J17+K17+L17 -> 7250044 | S17: =I17+J17+K17+L17 -> 7250044 | T17: =IF(R17-S17<0,R17-S17,0) -> 0 | U17: 250000 | V17: =IFERROR(__xludf.DUMMYFUNCTION("VLOOKUP(C17,IMPORTRANGE(""https://docs.google.com/spreadsheets/d/1ZLN5T8y7NSBIP1rvSj6TTUR_vTQbRwUKSt8zZJ_EfE4/edit?gid=461094331#gid=461094331"",""SCHEDULE_SDT_JAN26""),36,0)"),1) -> 1 | W17: =U17*V17 -> 250000 | X17: 0 | Y17: =I17+J17+K17+P17+W17+X17 -> 7500044 | Z17: =IFERROR(__xludf.DUMMYFUNCTION("VLOOKUP(C17,IMPORTRANGE(""https://docs.google.com/spreadsheets/d/1ZLN5T8y7NSBIP1rvSj6TTUR_vTQbRwUKSt8zZJ_EfE4/edit?gid=461094331#gid=461094331"",""SCHEDULE_SDT_JAN26""),38,0)+VLOOKUP(C17,IMPORTRANGE(""https://docs.google.com/spreadsheets/d/1ZLN5T8y7NSBIP1"&"rvSj6TTUR_vTQbRwUKSt8zZJ_EfE4/edit?gid=461094331#gid=461094331"",""SCHEDULE_SDT_JAN26""),39,0)"),0) -> 0 | AA17: =IFERROR(__xludf.DUMMYFUNCTION("VLOOKUP(C17,IMPORTRANGE(""https://docs.google.com/spreadsheets/d/1ZLN5T8y7NSBIP1rvSj6TTUR_vTQbRwUKSt8zZJ_EfE4/edit?gid=461094331#gid=461094331"",""SCHEDULE_SDT_JAN26""),40,0)"),0) -> 0 | AB17: =IFERROR(__xludf.DUMMYFUNCTION("VLOOKUP(C17,IMPORTRANGE(""https://docs.google.com/spreadsheets/d/1ZLN5T8y7NSBIP1rvSj6TTUR_vTQbRwUKSt8zZJ_EfE4/edit?gid=461094331#gid=461094331"",""SCHEDULE_SDT_JAN26""),41,0)"),0) -> 0 | AC17: =IFERROR(__xludf.DUMMYFUNCTION("VLOOKUP(C17,IMPORTRANGE(""https://docs.google.com/spreadsheets/d/1ZLN5T8y7NSBIP1rvSj6TTUR_vTQbRwUKSt8zZJ_EfE4/edit?gid=461094331#gid=461094331"",""SCHEDULE_SDT_JAN26""),42,0)"),0) -> 0 | AD17: =IFERROR(__xludf.DUMMYFUNCTION("VLOOKUP(C17,IMPORTRANGE(""https://docs.google.com/spreadsheets/d/1ZLN5T8y7NSBIP1rvSj6TTUR_vTQbRwUKSt8zZJ_EfE4/edit?gid=461094331#gid=461094331"",""SCHEDULE_SDT_JAN26""),43,0)"),0) -> 0 | AE17: =U17*(Z17+AA17+AD17+(AC17)) -> 0 | AF17: 468468 | AG17: 253500 | AH17: 0 | AI17: 0 | AJ17: 0 | AK17: =AI17-AJ17 -> 0 | AL17: 0 | AM17: =AE17+AF17+AG17+AH17+AJ17+AL17 -> 721968 | AN17: =Y17-AM17 -> 6778076 | AO17: =BE17 -> 90500.155 | AP17: =AN17-AO17 -> 6687575.8 | AQ17: =AP17-X17 -> 6687575.8 | AR17: =IF(AQ17>0,ROUND(AQ17,-2),0) -> 6687600 | AT17: TK/0 | AU17: A | AV17: =I17 -> 5729876 | AW17: =P17 -> 1000000 | AX17: =W17 -> 250000 | AY17: 0 | AZ17: =IF(J17=0,0,AV17*0.24%) -> 13751.702 | BA17: =IF(J17=0,0,AV17*0.3%) -> 17189.628 | BB17: =IF(K17=0,0,AV17*4%) -> 229195.04 | BC17: =SUM(AV17:BB17) -> 7240012.4 | BD17: =IF(AU17="C",VLOOKUP(BC17,TER!$J$4:$L$50,3,TRUE),IF(AU17="B",VLOOKUP(BC17,TER!$F$4:$H$50,3,TRUE),IF(AU17="A",VLOOKUP(BC17,TER!$B$4:$D$50,3,TRUE),"ERROR"))) -> 0.0125 | BE17: =BC17*BD17 -> 90500.155
B18: 12 | C18: 3172030708790016 | D18: WAL ASRI | E18: BRI | F18: 065101021358502 | G18: ANGGOTA | H18: FULL - EXISTING | I18: =IF(H18="FULL - EXISTING",5729876,5729876/O18*N18) -> 5729876 | J18: 316368 | K18: 203800 | L18: 1000000 | M18: =L18/O18 -> 47619.048 | N18: =IFERROR(__xludf.DUMMYFUNCTION("VLOOKUP(C18,IMPORTRANGE(""https://docs.google.com/spreadsheets/d/1ZLN5T8y7NSBIP1rvSj6TTUR_vTQbRwUKSt8zZJ_EfE4/edit?gid=461094331#gid=461094331"",""SCHEDULE_SDT_JAN26""),35,0)"),20) -> 20 | O18: =IFERROR(__xludf.DUMMYFUNCTION("VLOOKUP(C18,IMPORTRANGE(""https://docs.google.com/spreadsheets/d/1ZLN5T8y7NSBIP1rvSj6TTUR_vTQbRwUKSt8zZJ_EfE4/edit?gid=461094331#gid=461094331"",""SCHEDULE_SDT_JAN26""),34,0)"),21) -> 21 | P18: =M18*N18 -> 952380.95 | R18: =I18+J18+K18+L18 -> 7250044 | S18: =I18+J18+K18+L18 -> 7250044 | T18: =IF(R18-S18<0,R18-S18,0) -> 0 | U18: 250000 | V18: =IFERROR(__xludf.DUMMYFUNCTION("VLOOKUP(C18,IMPORTRANGE(""https://docs.google.com/spreadsheets/d/1ZLN5T8y7NSBIP1rvSj6TTUR_vTQbRwUKSt8zZJ_EfE4/edit?gid=461094331#gid=461094331"",""SCHEDULE_SDT_JAN26""),36,0)"),1) -> 1 | W18: =U18*V18 -> 250000 | X18: 0 | Y18: =I18+J18+K18+P18+W18+X18 -> 7452425 | Z18: =IFERROR(__xludf.DUMMYFUNCTION("VLOOKUP(C18,IMPORTRANGE(""https://docs.google.com/spreadsheets/d/1ZLN5T8y7NSBIP1rvSj6TTUR_vTQbRwUKSt8zZJ_EfE4/edit?gid=461094331#gid=461094331"",""SCHEDULE_SDT_JAN26""),38,0)+VLOOKUP(C18,IMPORTRANGE(""https://docs.google.com/spreadsheets/d/1ZLN5T8y7NSBIP1"&"rvSj6TTUR_vTQbRwUKSt8zZJ_EfE4/edit?gid=461094331#gid=461094331"",""SCHEDULE_SDT_JAN26""),39,0)"),0) -> 0 | AA18: =IFERROR(__xludf.DUMMYFUNCTION("VLOOKUP(C18,IMPORTRANGE(""https://docs.google.com/spreadsheets/d/1ZLN5T8y7NSBIP1rvSj6TTUR_vTQbRwUKSt8zZJ_EfE4/edit?gid=461094331#gid=461094331"",""SCHEDULE_SDT_JAN26""),40,0)"),1) -> 1 | AB18: =IFERROR(__xludf.DUMMYFUNCTION("VLOOKUP(C18,IMPORTRANGE(""https://docs.google.com/spreadsheets/d/1ZLN5T8y7NSBIP1rvSj6TTUR_vTQbRwUKSt8zZJ_EfE4/edit?gid=461094331#gid=461094331"",""SCHEDULE_SDT_JAN26""),41,0)"),0) -> 0 | AC18: =IFERROR(__xludf.DUMMYFUNCTION("VLOOKUP(C18,IMPORTRANGE(""https://docs.google.com/spreadsheets/d/1ZLN5T8y7NSBIP1rvSj6TTUR_vTQbRwUKSt8zZJ_EfE4/edit?gid=461094331#gid=461094331"",""SCHEDULE_SDT_JAN26""),42,0)"),0) -> 0 | AD18: =IFERROR(__xludf.DUMMYFUNCTION("VLOOKUP(C18,IMPORTRANGE(""https://docs.google.com/spreadsheets/d/1ZLN5T8y7NSBIP1rvSj6TTUR_vTQbRwUKSt8zZJ_EfE4/edit?gid=461094331#gid=461094331"",""SCHEDULE_SDT_JAN26""),43,0)"),0) -> 0 | AE18: =U18*(Z18+AA18+AD18+(AC18)) -> 250000 | AF18: 468468 | AG18: 253500 | AH18: 0 | AI18: 0 | AJ18: 0 | AK18: =AI18-AJ18 -> 0 | AL18: 0 | AM18: =AE18+AF18+AG18+AH18+AJ18+AL18 -> 971968 | AN18: =Y18-AM18 -> 6480457 | AO18: =BE18 -> 53942.95 | AP18: =AN18-AO18 -> 6426514 | AQ18: =AP18-X18 -> 6426514 | AR18: =IF(AQ18>0,ROUND(AQ18,-2),0) -> 6426500 | AT18: K/2 | AU18: B | AV18: =I18 -> 5729876 | AW18: =P18 -> 952380.95 | AX18: =W18 -> 250000 | AY18: 0 | AZ18: =IF(J18=0,0,AV18*0.24%) -> 13751.702 | BA18: =IF(J18=0,0,AV18*0.3%) -> 17189.628 | BB18: =IF(K18=0,0,AV18*4%) -> 229195.04 | BC18: =SUM(AV18:BB18) -> 7192393.3 | BD18: =IF(AU18="C",VLOOKUP(BC18,TER!$J$4:$L$50,3,TRUE),IF(AU18="B",VLOOKUP(BC18,TER!$F$4:$H$50,3,TRUE),IF(AU18="A",VLOOKUP(BC18,TER!$B$4:$D$50,3,TRUE),"ERROR"))) -> 0.0075 | BE18: =BC18*BD18 -> 53942.95
B19: 13 | C19: 3172033008040012 | D19: BAGUS SETIAWAN | E19: BRI | F19: 065101021326505 | G19: ANGGOTA | H19: FULL - EXISTING | I19: =IF(H19="FULL - EXISTING",5729876,5729876/O19*N19) -> 5729876 | J19: 316368 | K19: 203800 | L19: 100000 | M19: =L19/O19 -> 4761.9048 | N19: =IFERROR(__xludf.DUMMYFUNCTION("VLOOKUP(C19,IMPORTRANGE(""https://docs.google.com/spreadsheets/d/1ZLN5T8y7NSBIP1rvSj6TTUR_vTQbRwUKSt8zZJ_EfE4/edit?gid=461094331#gid=461094331"",""SCHEDULE_SDT_JAN26""),35,0)"),20) -> 20 | O19: =IFERROR(__xludf.DUMMYFUNCTION("VLOOKUP(C19,IMPORTRANGE(""https://docs.google.com/spreadsheets/d/1ZLN5T8y7NSBIP1rvSj6TTUR_vTQbRwUKSt8zZJ_EfE4/edit?gid=461094331#gid=461094331"",""SCHEDULE_SDT_JAN26""),34,0)"),21) -> 21 | P19: =M19*N19 -> 95238.095 | R19: =I19+J19+K19+L19 -> 6350044 | S19: =I19+J19+K19+L19 -> 6350044 | T19: =IF(R19-S19<0,R19-S19,0) -> 0 | U19: 250000 | V19: =IFERROR(__xludf.DUMMYFUNCTION("VLOOKUP(C19,IMPORTRANGE(""https://docs.google.com/spreadsheets/d/1ZLN5T8y7NSBIP1rvSj6TTUR_vTQbRwUKSt8zZJ_EfE4/edit?gid=461094331#gid=461094331"",""SCHEDULE_SDT_JAN26""),36,0)"),1) -> 1 | W19: =U19*V19 -> 250000 | X19: 0 | Y19: =I19+J19+K19+P19+W19+X19 -> 6595282.1 | Z19: =IFERROR(__xludf.DUMMYFUNCTION("VLOOKUP(C19,IMPORTRANGE(""https://docs.google.com/spreadsheets/d/1ZLN5T8y7NSBIP1rvSj6TTUR_vTQbRwUKSt8zZJ_EfE4/edit?gid=461094331#gid=461094331"",""SCHEDULE_SDT_JAN26""),38,0)+VLOOKUP(C19,IMPORTRANGE(""https://docs.google.com/spreadsheets/d/1ZLN5T8y7NSBIP1"&"rvSj6TTUR_vTQbRwUKSt8zZJ_EfE4/edit?gid=461094331#gid=461094331"",""SCHEDULE_SDT_JAN26""),39,0)"),0) -> 0 | AA19: =IFERROR(__xludf.DUMMYFUNCTION("VLOOKUP(C19,IMPORTRANGE(""https://docs.google.com/spreadsheets/d/1ZLN5T8y7NSBIP1rvSj6TTUR_vTQbRwUKSt8zZJ_EfE4/edit?gid=461094331#gid=461094331"",""SCHEDULE_SDT_JAN26""),40,0)"),1) -> 1 | AB19: =IFERROR(__xludf.DUMMYFUNCTION("VLOOKUP(C19,IMPORTRANGE(""https://docs.google.com/spreadsheets/d/1ZLN5T8y7NSBIP1rvSj6TTUR_vTQbRwUKSt8zZJ_EfE4/edit?gid=461094331#gid=461094331"",""SCHEDULE_SDT_JAN26""),41,0)"),0) -> 0 | AC19: =IFERROR(__xludf.DUMMYFUNCTION("VLOOKUP(C19,IMPORTRANGE(""https://docs.google.com/spreadsheets/d/1ZLN5T8y7NSBIP1rvSj6TTUR_vTQbRwUKSt8zZJ_EfE4/edit?gid=461094331#gid=461094331"",""SCHEDULE_SDT_JAN26""),42,0)"),0) -> 0 | AD19: =IFERROR(__xludf.DUMMYFUNCTION("VLOOKUP(C19,IMPORTRANGE(""https://docs.google.com/spreadsheets/d/1ZLN5T8y7NSBIP1rvSj6TTUR_vTQbRwUKSt8zZJ_EfE4/edit?gid=461094331#gid=461094331"",""SCHEDULE_SDT_JAN26""),43,0)"),0) -> 0 | AE19: =U19*(Z19+AA19+AD19+(AC19)) -> 250000 | AF19: 468468 | AG19: 253500 | AH19: 0 | AI19: 0 | AJ19: 0 | AK19: =AI19-AJ19 -> 0 | AL19: 0 | AM19: =AE19+AF19+AG19+AH19+AJ19+AL19 -> 971968 | AN19: =Y19-AM19 -> 5623314.1 | AO19: =BE19 -> 0 | AP19: =AN19-AO19 -> 5623314.1 | AQ19: =AP19-X19 -> 5623314.1 | AR19: =IF(AQ19>0,ROUND(AQ19,-2),0) -> 5623300 | AT19: K/3 | AU19: C | AV19: =I19 -> 5729876 | AW19: =P19 -> 95238.095 | AX19: =W19 -> 250000 | AY19: 0 | AZ19: =IF(J19=0,0,AV19*0.24%) -> 13751.702 | BA19: =IF(J19=0,0,AV19*0.3%) -> 17189.628 | BB19: =IF(K19=0,0,AV19*4%) -> 229195.04 | BC19: =SUM(AV19:BB19) -> 6335250.5 | BD19: =IF(AU19="C",VLOOKUP(BC19,TER!$J$4:$L$50,3,TRUE),IF(AU19="B",VLOOKUP(BC19,TER!$F$4:$H$50,3,TRUE),IF(AU19="A",VLOOKUP(BC19,TER!$B$4:$D$50,3,TRUE),"ERROR"))) -> 0 | BE19: =BC19*BD19 -> 0
B20: 14 | C20: 1371052605850003 | D20: BUDI YANTO | E20: BRI | F20: 065101021329503 | G20: ANGGOTA | H20: FULL - EXISTING | I20: =IF(H20="FULL - EXISTING",5729876,5729876/O20*N20) -> 5729876 | J20: 316368 | K20: 203800 | L20: 200000 | M20: =L20/O20 -> 9523.8095 | N20: =IFERROR(__xludf.DUMMYFUNCTION("VLOOKUP(C20,IMPORTRANGE(""https://docs.google.com/spreadsheets/d/1ZLN5T8y7NSBIP1rvSj6TTUR_vTQbRwUKSt8zZJ_EfE4/edit?gid=461094331#gid=461094331"",""SCHEDULE_SDT_JAN26""),35,0)"),21) -> 21 | O20: =IFERROR(__xludf.DUMMYFUNCTION("VLOOKUP(C20,IMPORTRANGE(""https://docs.google.com/spreadsheets/d/1ZLN5T8y7NSBIP1rvSj6TTUR_vTQbRwUKSt8zZJ_EfE4/edit?gid=461094331#gid=461094331"",""SCHEDULE_SDT_JAN26""),34,0)"),21) -> 21 | P20: =M20*N20 -> 200000 | R20: =I20+J20+K20+L20 -> 6450044 | S20: =I20+J20+K20+L20 -> 6450044 | T20: =IF(R20-S20<0,R20-S20,0) -> 0 | U20: 250000 | V20: =IFERROR(__xludf.DUMMYFUNCTION("VLOOKUP(C20,IMPORTRANGE(""https://docs.google.com/spreadsheets/d/1ZLN5T8y7NSBIP1rvSj6TTUR_vTQbRwUKSt8zZJ_EfE4/edit?gid=461094331#gid=461094331"",""SCHEDULE_SDT_JAN26""),36,0)"),2) -> 2 | W20: =U20*V20 -> 500000 | X20: 0 | Y20: =I20+J20+K20+P20+W20+X20 -> 6950044 | Z20: =IFERROR(__xludf.DUMMYFUNCTION("VLOOKUP(C20,IMPORTRANGE(""https://docs.google.com/spreadsheets/d/1ZLN5T8y7NSBIP1rvSj6TTUR_vTQbRwUKSt8zZJ_EfE4/edit?gid=461094331#gid=461094331"",""SCHEDULE_SDT_JAN26""),38,0)+VLOOKUP(C20,IMPORTRANGE(""https://docs.google.com/spreadsheets/d/1ZLN5T8y7NSBIP1"&"rvSj6TTUR_vTQbRwUKSt8zZJ_EfE4/edit?gid=461094331#gid=461094331"",""SCHEDULE_SDT_JAN26""),39,0)"),0) -> 0 | AA20: =IFERROR(__xludf.DUMMYFUNCTION("VLOOKUP(C20,IMPORTRANGE(""https://docs.google.com/spreadsheets/d/1ZLN5T8y7NSBIP1rvSj6TTUR_vTQbRwUKSt8zZJ_EfE4/edit?gid=461094331#gid=461094331"",""SCHEDULE_SDT_JAN26""),40,0)"),0) -> 0 | AB20: =IFERROR(__xludf.DUMMYFUNCTION("VLOOKUP(C20,IMPORTRANGE(""https://docs.google.com/spreadsheets/d/1ZLN5T8y7NSBIP1rvSj6TTUR_vTQbRwUKSt8zZJ_EfE4/edit?gid=461094331#gid=461094331"",""SCHEDULE_SDT_JAN26""),41,0)"),0) -> 0 | AC20: =IFERROR(__xludf.DUMMYFUNCTION("VLOOKUP(C20,IMPORTRANGE(""https://docs.google.com/spreadsheets/d/1ZLN5T8y7NSBIP1rvSj6TTUR_vTQbRwUKSt8zZJ_EfE4/edit?gid=461094331#gid=461094331"",""SCHEDULE_SDT_JAN26""),42,0)"),0) -> 0 | AD20: =IFERROR(__xludf.DUMMYFUNCTION("VLOOKUP(C20,IMPORTRANGE(""https://docs.google.com/spreadsheets/d/1ZLN5T8y7NSBIP1rvSj6TTUR_vTQbRwUKSt8zZJ_EfE4/edit?gid=461094331#gid=461094331"",""SCHEDULE_SDT_JAN26""),43,0)"),0) -> 0 | AE20: =U20*(Z20+AA20+AD20+(AC20)) -> 0 | AF20: 468468 | AG20: 253500 | AH20: 0 | AI20: 0 | AJ20: 0 | AK20: =AI20-AJ20 -> 0 | AL20: 0 | AM20: =AE20+AF20+AG20+AH20+AJ20+AL20 -> 721968 | AN20: =Y20-AM20 -> 6228076 | AO20: =BE20 -> 66900.124 | AP20: =AN20-AO20 -> 6161175.9 | AQ20: =AP20-X20 -> 6161175.9 | AR20: =IF(AQ20>0,ROUND(AQ20,-2),0) -> 6161200 | AT20: TK/0 | AU20: A | AV20: =I20 -> 5729876 | AW20: =P20 -> 200000 | AX20: =W20 -> 500000 | AY20: 0 | AZ20: =IF(J20=0,0,AV20*0.24%) -> 13751.702 | BA20: =IF(J20=0,0,AV20*0.3%) -> 17189.628 | BB20: =IF(K20=0,0,AV20*4%) -> 229195.04 | BC20: =SUM(AV20:BB20) -> 6690012.4 | BD20: =IF(AU20="C",VLOOKUP(BC20,TER!$J$4:$L$50,3,TRUE),IF(AU20="B",VLOOKUP(BC20,TER!$F$4:$H$50,3,TRUE),IF(AU20="A",VLOOKUP(BC20,TER!$B$4:$D$50,3,TRUE),"ERROR"))) -> 0.01 | BE20: =BC20*BD20 -> 66900.124
B21: 15 | C21: 3674050510860005 | D21: BAYU EKA MARIO | E21: BRI | F21: 065101021362501 | G21: ANGGOTA | H21: FULL - EXISTING | I21: =IF(H21="FULL - EXISTING",5729876,5729876/O21*N21) -> 5729876 | J21: 316368 | K21: 203800 | L21: 200000 | M21: =L21/O21 -> 10000 | N21: =IFERROR(__xludf.DUMMYFUNCTION("VLOOKUP(C21,IMPORTRANGE(""https://docs.google.com/spreadsheets/d/1ZLN5T8y7NSBIP1rvSj6TTUR_vTQbRwUKSt8zZJ_EfE4/edit?gid=461094331#gid=461094331"",""SCHEDULE_SDT_JAN26""),35,0)"),19) -> 19 | O21: =IFERROR(__xludf.DUMMYFUNCTION("VLOOKUP(C21,IMPORTRANGE(""https://docs.google.com/spreadsheets/d/1ZLN5T8y7NSBIP1rvSj6TTUR_vTQbRwUKSt8zZJ_EfE4/edit?gid=461094331#gid=461094331"",""SCHEDULE_SDT_JAN26""),34,0)"),20) -> 20 | P21: =M21*N21 -> 190000 | R21: =I21+J21+K21+L21 -> 6450044 | S21: =I21+J21+K21+L21 -> 6450044 | T21: =IF(R21-S21<0,R21-S21,0) -> 0 | U21: 250000 | V21: =IFERROR(__xludf.DUMMYFUNCTION("VLOOKUP(C21,IMPORTRANGE(""https://docs.google.com/spreadsheets/d/1ZLN5T8y7NSBIP1rvSj6TTUR_vTQbRwUKSt8zZJ_EfE4/edit?gid=461094331#gid=461094331"",""SCHEDULE_SDT_JAN26""),36,0)"),2) -> 2 | W21: =U21*V21 -> 500000 | X21: 0 | Y21: =I21+J21+K21+P21+W21+X21 -> 6940044 | Z21: =IFERROR(__xludf.DUMMYFUNCTION("VLOOKUP(C21,IMPORTRANGE(""https://docs.google.com/spreadsheets/d/1ZLN5T8y7NSBIP1rvSj6TTUR_vTQbRwUKSt8zZJ_EfE4/edit?gid=461094331#gid=461094331"",""SCHEDULE_SDT_JAN26""),38,0)+VLOOKUP(C21,IMPORTRANGE(""https://docs.google.com/spreadsheets/d/1ZLN5T8y7NSBIP1"&"rvSj6TTUR_vTQbRwUKSt8zZJ_EfE4/edit?gid=461094331#gid=461094331"",""SCHEDULE_SDT_JAN26""),39,0)"),0) -> 0 | AA21: =IFERROR(__xludf.DUMMYFUNCTION("VLOOKUP(C21,IMPORTRANGE(""https://docs.google.com/spreadsheets/d/1ZLN5T8y7NSBIP1rvSj6TTUR_vTQbRwUKSt8zZJ_EfE4/edit?gid=461094331#gid=461094331"",""SCHEDULE_SDT_JAN26""),40,0)"),1) -> 1 | AB21: =IFERROR(__xludf.DUMMYFUNCTION("VLOOKUP(C21,IMPORTRANGE(""https://docs.google.com/spreadsheets/d/1ZLN5T8y7NSBIP1rvSj6TTUR_vTQbRwUKSt8zZJ_EfE4/edit?gid=461094331#gid=461094331"",""SCHEDULE_SDT_JAN26""),41,0)"),0) -> 0 | AC21: =IFERROR(__xludf.DUMMYFUNCTION("VLOOKUP(C21,IMPORTRANGE(""https://docs.google.com/spreadsheets/d/1ZLN5T8y7NSBIP1rvSj6TTUR_vTQbRwUKSt8zZJ_EfE4/edit?gid=461094331#gid=461094331"",""SCHEDULE_SDT_JAN26""),42,0)"),0) -> 0 | AD21: =IFERROR(__xludf.DUMMYFUNCTION("VLOOKUP(C21,IMPORTRANGE(""https://docs.google.com/spreadsheets/d/1ZLN5T8y7NSBIP1rvSj6TTUR_vTQbRwUKSt8zZJ_EfE4/edit?gid=461094331#gid=461094331"",""SCHEDULE_SDT_JAN26""),43,0)"),0) -> 0 | AE21: =U21*(Z21+AA21+AD21+(AC21)) -> 250000 | AF21: 468468 | AG21: 253500 | AH21: 0 | AI21: 0 | AJ21: 0 | AK21: =AI21-AJ21 -> 0 | AL21: 0 | AM21: =AE21+AF21+AG21+AH21+AJ21+AL21 -> 971968 | AN21: =Y21-AM21 -> 5968076 | AO21: =BE21 -> 66800.124 | AP21: =AN21-AO21 -> 5901275.9 | AQ21: =AP21-X21 -> 5901275.9 | AR21: =IF(AQ21>0,ROUND(AQ21,-2),0) -> 5901300 | AT21: K/0 | AU21: A | AV21: =I21 -> 5729876 | AW21: =P21 -> 190000 | AX21: =W21 -> 500000 | AY21: 0 | AZ21: =IF(J21=0,0,AV21*0.24%) -> 13751.702 | BA21: =IF(J21=0,0,AV21*0.3%) -> 17189.628 | BB21: =IF(K21=0,0,AV21*4%) -> 229195.04 | BC21: =SUM(AV21:BB21) -> 6680012.4 | BD21: =IF(AU21="C",VLOOKUP(BC21,TER!$J$4:$L$50,3,TRUE),IF(AU21="B",VLOOKUP(BC21,TER!$F$4:$H$50,3,TRUE),IF(AU21="A",VLOOKUP(BC21,TER!$B$4:$D$50,3,TRUE),"ERROR"))) -> 0.01 | BE21: =BC21*BD21 -> 66800.124
B22: 16 | C22: 3275021012980011 | D22: MOHAMAD EKA FADHILLAH | E22: BRI | F22: 065101021369503 | G22: ANGGOTA | H22: FULL - EXISTING | I22: =IF(H22="FULL - EXISTING",5729876,5729876/O22*N22) -> 5729876 | J22: 316368 | K22: 203800 | L22: 200000 | M22: =L22/O22 -> 10000 | N22: =IFERROR(__xludf.DUMMYFUNCTION("VLOOKUP(C22,IMPORTRANGE(""https://docs.google.com/spreadsheets/d/1ZLN5T8y7NSBIP1rvSj6TTUR_vTQbRwUKSt8zZJ_EfE4/edit?gid=461094331#gid=461094331"",""SCHEDULE_SDT_JAN26""),35,0)"),3) -> 3 | O22: =IFERROR(__xludf.DUMMYFUNCTION("VLOOKUP(C22,IMPORTRANGE(""https://docs.google.com/spreadsheets/d/1ZLN5T8y7NSBIP1rvSj6TTUR_vTQbRwUKSt8zZJ_EfE4/edit?gid=461094331#gid=461094331"",""SCHEDULE_SDT_JAN26""),34,0)"),20) -> 20 | P22: =M22*N22 -> 30000 | R22: =I22+J22+K22+L22 -> 6450044 | S22: =I22+J22+K22+L22 -> 6450044 | T22: =IF(R22-S22<0,R22-S22,0) -> 0 | U22: 250000 | V22: =IFERROR(__xludf.DUMMYFUNCTION("VLOOKUP(C22,IMPORTRANGE(""https://docs.google.com/spreadsheets/d/1ZLN5T8y7NSBIP1rvSj6TTUR_vTQbRwUKSt8zZJ_EfE4/edit?gid=461094331#gid=461094331"",""SCHEDULE_SDT_JAN26""),36,0)"),1) -> 1 | W22: =U22*V22 -> 250000 | X22: 0 | Y22: =I22+J22+K22+P22+W22+X22 -> 6530044 | Z22: =IFERROR(__xludf.DUMMYFUNCTION("VLOOKUP(C22,IMPORTRANGE(""https://docs.google.com/spreadsheets/d/1ZLN5T8y7NSBIP1rvSj6TTUR_vTQbRwUKSt8zZJ_EfE4/edit?gid=461094331#gid=461094331"",""SCHEDULE_SDT_JAN26""),38,0)+VLOOKUP(C22,IMPORTRANGE(""https://docs.google.com/spreadsheets/d/1ZLN5T8y7NSBIP1"&"rvSj6TTUR_vTQbRwUKSt8zZJ_EfE4/edit?gid=461094331#gid=461094331"",""SCHEDULE_SDT_JAN26""),39,0)"),0) -> 0 | AA22: =IFERROR(__xludf.DUMMYFUNCTION("VLOOKUP(C22,IMPORTRANGE(""https://docs.google.com/spreadsheets/d/1ZLN5T8y7NSBIP1rvSj6TTUR_vTQbRwUKSt8zZJ_EfE4/edit?gid=461094331#gid=461094331"",""SCHEDULE_SDT_JAN26""),40,0)"),0) -> 0 | AB22: =IFERROR(__xludf.DUMMYFUNCTION("VLOOKUP(C22,IMPORTRANGE(""https://docs.google.com/spreadsheets/d/1ZLN5T8y7NSBIP1rvSj6TTUR_vTQbRwUKSt8zZJ_EfE4/edit?gid=461094331#gid=461094331"",""SCHEDULE_SDT_JAN26""),41,0)"),0) -> 0 | AC22: =IFERROR(__xludf.DUMMYFUNCTION("VLOOKUP(C22,IMPORTRANGE(""https://docs.google.com/spreadsheets/d/1ZLN5T8y7NSBIP1rvSj6TTUR_vTQbRwUKSt8zZJ_EfE4/edit?gid=461094331#gid=461094331"",""SCHEDULE_SDT_JAN26""),42,0)"),0) -> 0 | AD22: =IFERROR(__xludf.DUMMYFUNCTION("VLOOKUP(C22,IMPORTRANGE(""https://docs.google.com/spreadsheets/d/1ZLN5T8y7NSBIP1rvSj6TTUR_vTQbRwUKSt8zZJ_EfE4/edit?gid=461094331#gid=461094331"",""SCHEDULE_SDT_JAN26""),43,0)"),0) -> 0 | AE22: =U22*(Z22+AA22+AD22+(AC22)) -> 0 | AF22: 468468 | AG22: 253500 | AH22: 0 | AI22: 0 | AJ22: 0 | AK22: =AI22-AJ22 -> 0 | AL22: 0 | AM22: =AE22+AF22+AG22+AH22+AJ22+AL22 -> 721968 | AN22: =Y22-AM22 -> 5808076 | AO22: =BE22 -> 47025.093 | AP22: =AN22-AO22 -> 5761050.9 | AQ22: =AP22-X22 -> 5761050.9 | AR22: =IF(AQ22>0,ROUND(AQ22,-2),0) -> 5761100 | AT22: TK/0 | AU22: A | AV22: =I22 -> 5729876 | AW22: =P22 -> 30000 | AX22: =W22 -> 250000 | AY22: 0 | AZ22: =IF(J22=0,0,AV22*0.24%) -> 13751.702 | BA22: =IF(J22=0,0,AV22*0.3%) -> 17189.628 | BB22: =IF(K22=0,0,AV22*4%) -> 229195.04 | BC22: =SUM(AV22:BB22) -> 6270012.4 | BD22: =IF(AU22="C",VLOOKUP(BC22,TER!$J$4:$L$50,3,TRUE),IF(AU22="B",VLOOKUP(BC22,TER!$F$4:$H$50,3,TRUE),IF(AU22="A",VLOOKUP(BC22,TER!$B$4:$D$50,3,TRUE),"ERROR"))) -> 0.0075 | BE22: =BC22*BD22 -> 47025.093
